<?xml version="1.0" ?>
<!-- =================================================================================== -->
<!-- |    This document was autogenerated by xacro from mir.urdf.xacro                 | -->
<!-- |    EDITING THIS FILE BY HAND IS NOT RECOMMENDED                                 | -->
<!-- =================================================================================== -->
<robot name="mir_m0609_ppr">
  <link name="world">
      <inertial>
          <mass value="0.000001" />
          <origin xyz="0.0 0.0 0.0" rpy="0 0 0" />
          <inertia ixx="0.000001" ixy="0" ixz="0" iyy="0.000001" iyz="0" izz="0.000001" />
      </inertial>
  </link>
  <joint name="lin_x_joint" type="prismatic">
    <origin rpy="0 0 0" xyz="0 0 0"/>
    <axis xyz="1 0 0"/>
    <limit effort="1000.0" lower="-1e+16" upper="1e+16" velocity="3.5"/>
    <joint_properties damping="1" friction="1"/>
    <parent link="world"/>
    <child link="lin_x_link"/>
  </joint>
  <link name="lin_x_link">
      <inertial>
          <mass value="0.000001" />
          <origin xyz="0.0 0.0 0.0" rpy="0 0 0" />
          <inertia ixx="0.000001" ixy="0" ixz="0" iyy="0.000001" iyz="0" izz="0.000001" />
      </inertial>
  </link>
  <joint name="lin_y_joint" type="prismatic">
    <origin rpy="0 0 0" xyz="0 0 0"/>
    <axis xyz="0 1 0"/>
    <limit effort="1000.0" lower="-1e+16" upper="1e+16" velocity="3.5"/>
    <joint_properties damping="1" friction="1"/>
    <parent link="lin_x_link"/>
    <child link="lin_y_link"/>
  </joint>
  <link name="lin_y_link">
      <inertial>
          <mass value="0.000001" />
          <origin xyz="0.0 0.0 0.0" rpy="0 0 0" />
          <inertia ixx="0.000001" ixy="0" ixz="0" iyy="0.000001" iyz="0" izz="0.000001" />
      </inertial>
  </link>
  <joint name="rot_z_joint" type="revolute">
    <origin rpy="0 0 0" xyz="0 0 0"/>
    <axis xyz="0 0 1"/>
    <limit effort="1000.0" lower="-1e+16" upper="1e+16" velocity="3.5"/>
    <joint_properties damping="1" friction="1"/>
    <parent link="lin_y_link"/>
    <child link="base_link"/>
  </joint>

  <link name="base_footprint">
  <inertial>
          <mass value="0.000001" />
          <origin xyz="0.0 0.0 0.0" rpy="0 0 0" />
          <inertia ixx="0.000001" ixy="0" ixz="0" iyy="0.000001" iyz="0" izz="0.000001" />
      </inertial>
  </link>
  <joint name="base_joint" type="fixed">
    <parent link="base_link"/>
    <child link="base_footprint"/>
    <origin rpy="0 0 0" xyz="0 0 0"/>
  </joint>
  
  
  <link name="base_link">
    <inertial>
      <mass value="58.0"/>
      <origin rpy="0 0 0" xyz="0.037646 0 0.20"/>
      <inertia ixx="2.0609325089599997" ixy="0.0" ixz="0.0" iyy="4.34999826" iyz="0.0" izz="5.54093111696"/>
    </inertial>
    <visual>
      <origin rpy="0 0 0" xyz="0.037646 0 0"/>
      <geometry>
        <mesh filename="meshes/visual/mir_100_base.stl"/>
      </geometry>
      <material name="white">
        <color rgba="1 1 1 1"/>
      </material>
    </visual>
    <collision>
      <origin rpy="0 0 0" xyz="0.037646 0 0"/>
      <geometry>
        <mesh filename="meshes/collision/mir_100_base.stl"/>
      </geometry>
    </collision>
  </link>

  <!-- IMU -->
  <joint name="base_link_to_imu_joint" type="fixed">
    <parent link="base_link"/>
    <child link="imu_link"/>
    <origin rpy="0 0 0" xyz="0.0 0.0 0.25"/>
    <!-- same as real MiR -->
  </joint>
  <link name="imu_link">
  <inertial>
          <mass value="0.000001" />
          <origin xyz="0.0 0.0 0.0" rpy="0 0 0" />
          <inertia ixx="0.000001" ixy="0" ixz="0" iyy="0.000001" iyz="0" izz="0.000001" />
      </inertial>
  </link>

  <!-- Create an alias for imu_link. This is necessary because the real MiR's
         TF has imu_link, but the imu_data topic is published in the imu_frame
         frame. -->
  <joint name="imu_link_to_imu_frame_joint" type="fixed">
    <parent link="imu_link"/>
    <child link="imu_frame"/>
    <origin rpy="0 0 0" xyz="0 0 0"/>
  </joint>
  <link name="imu_frame">
  <inertial>
          <mass value="0.000001" />
          <origin xyz="0.0 0.0 0.0" rpy="0 0 0" />
          <inertia ixx="0.000001" ixy="0" ixz="0" iyy="0.000001" iyz="0" izz="0.000001" />
      </inertial>
  </link>
  <!-- Laser scanners -->
  <joint name="base_link_to_front_laser_joint" type="fixed">
    <parent link="base_link"/>
    <child link="front_laser_link"/>
    <origin rpy="0.0 0.0 0.7853981633974483" xyz="0.4288 0.2358 0.1914"/>
    <!-- from visually matching up the meshes of the MiR and the laser scanner -->
  </joint>
  <link name="front_laser_link">
    <visual>
      <origin rpy="3.141592653589793 0 0" xyz="0.0 0.0 0.0"/>
      <geometry>
        <mesh filename="meshes/visual/sick_lms-100.stl"/>
      </geometry>
      <!-- <xacro:insert_block name="material_yellow" /> -->
      <material name="black">
        <color rgba="0.1 0.1 0.1 1"/>
      </material>
    </visual>
    <collision>
      <origin rpy="3.141592653589793 0 0" xyz="0.0 0.0 0.0"/>
      <geometry>
        <mesh filename="meshes/visual/sick_lms-100.stl"/>
      </geometry>
    </collision>
    <inertial>
      <mass value="2.0"/>
      <origin xyz="0 0 0"/>
      <inertia ixx="0.009708329449999999" ixy="0.0" ixz="0.0" iyy="0.0097601627626" iyz="0.0" izz="0.0080601634426"/>
    </inertial>
  </link>

  <joint name="base_link_to_back_laser_joint" type="fixed">
    <parent link="base_link"/>
    <child link="back_laser_link"/>
    <origin rpy="0.0 0.0 -2.356194490192345" xyz="-0.3548 -0.2352 0.1914"/>
    <!-- from visually matching up the meshes of the MiR and the laser scanner -->
  </joint>
  <link name="back_laser_link">
    <visual>
      <origin rpy="3.141592653589793 0 0" xyz="0.0 0.0 0.0"/>
      <geometry>
        <mesh filename="meshes/visual/sick_lms-100.stl"/>
      </geometry>
      <!-- <xacro:insert_block name="material_yellow" /> -->
      <material name="black">
        <color rgba="0.1 0.1 0.1 1"/>
      </material>
    </visual>
    <collision>
      <origin rpy="3.141592653589793 0 0" xyz="0.0 0.0 0.0"/>
      <geometry>
        <mesh filename="meshes/visual/sick_lms-100.stl"/>
      </geometry>
    </collision>
    <inertial>
      <mass value="2.0"/>
      <origin xyz="0 0 0"/>
      <inertia ixx="0.009708329449999999" ixy="0.0" ixz="0.0" iyy="0.0097601627626" iyz="0.0" izz="0.0080601634426"/>
    </inertial>
  </link>

  <!-- Ultrasound sensors -->
  <joint name="us_1_joint" type="fixed">
    <!-- right ultrasound -->
    <parent link="base_link"/>
    <child link="us_1_frame"/>
    <origin rpy="0 0 0" xyz="0.45 -0.12 0.16 "/>
    <!-- from visually matching to the mesh of the MiR -->
  </joint>
  <link name="us_1_frame">
  <inertial>
          <mass value="0.000001" />
          <origin xyz="0.0 0.0 0.0" rpy="0 0 0" />
          <inertia ixx="0.000001" ixy="0" ixz="0" iyy="0.000001" iyz="0" izz="0.000001" />
      </inertial>
  </link>
  <joint name="us_2_joint" type="fixed">
    <!-- left ultrasound -->
    <parent link="base_link"/>
    <child link="us_2_frame"/>
    <origin rpy="0 0 0" xyz="0.45 0.12 0.16 "/>
    <!-- from visually matching to the mesh of the MiR -->
  </joint>
  <link name="us_2_frame">
  <inertial>
          <mass value="0.000001" />
          <origin xyz="0.0 0.0 0.0" rpy="0 0 0" />
          <inertia ixx="0.000001" ixy="0" ixz="0" iyy="0.000001" iyz="0" izz="0.000001" />
      </inertial>
  </link>
  <joint name="left_wheel_joint" type="fixed">
    <origin rpy="0 0 0" xyz="0.0 0.222604 0.0625"/>
    <parent link="base_link"/>
    <child link="left_wheel_link"/>
    <axis xyz="0 1 0"/>
    <limit effort="100" velocity="20.0"/>
  </joint>
  <link name="left_wheel_link">
    <inertial>
      <mass value="1.0"/>
      <origin rpy="1.5707963267948966 0 0" xyz="0 0 0"/>
      <inertia ixx="0.001061895408575" ixy="0.0" ixz="0.0" iyy="0.001061895408575" iyz="0.0" izz="0.001953125"/>
    </inertial>
    <visual>
      <origin rpy="0 0 0" xyz="0 0 0"/>
      <geometry>
        <mesh filename="meshes/visual/wheel.stl"/>
      </geometry>
      <material name="dark_grey">
        <color rgba="0.3 0.3 0.3 1"/>
      </material>
    </visual>
    <collision>
      <origin rpy="1.5707963267948966 0 0" xyz="0 0 0"/>
      <geometry>
        <cylinder length="0.032" radius="0.0625"/>
      </geometry>
    </collision>
  </link>

  <joint name="right_wheel_joint" type="fixed">
    <origin rpy="0 0 0" xyz="0.0 -0.222604 0.0625"/>
    <parent link="base_link"/>
    <child link="right_wheel_link"/>
    <axis xyz="0 1 0"/>
    <limit effort="100" velocity="20.0"/>
  </joint>
  <link name="right_wheel_link">
    <inertial>
      <mass value="1.0"/>
      <origin rpy="1.5707963267948966 0 0" xyz="0 0 0"/>
      <inertia ixx="0.001061895408575" ixy="0.0" ixz="0.0" iyy="0.001061895408575" iyz="0.0" izz="0.001953125"/>
    </inertial>
    <visual>
      <origin rpy="0 0 0" xyz="0 0 0"/>
      <geometry>
        <mesh filename="meshes/visual/wheel.stl"/>
      </geometry>
      <material name="dark_grey">
        <color rgba="0.3 0.3 0.3 1"/>
      </material>
    </visual>
    <collision>
      <origin rpy="1.5707963267948966 0 0" xyz="0 0 0"/>
      <geometry>
        <cylinder length="0.032" radius="0.0625"/>
      </geometry>
    </collision>
  </link>

  <!-- caster hub -->
  <joint name="fl_caster_rotation_joint" type="fixed">
    <origin rpy="0 0 0" xyz="0.341346 0.203 0.1565"/>
    <parent link="base_link"/>
    <child link="fl_caster_rotation_link"/>
    <axis xyz="0 0 1"/>
    <dynamics damping="0.01" friction="0.0"/>
  </joint>
  <link name="fl_caster_rotation_link">
    <inertial>
      <!-- <origin xyz="0 0 -0.042500000044" rpy="${0.5 * pi} ${24 * deg_to_rad} ${1.5 * pi}" /> -->
      <origin rpy="0.41887903200000004 0 1.5707963267948966 " xyz="0 0 -0.042500000044"/>
      <mass value="0.3097539019"/>
      <inertia ixx="0.0005844517978" ixy="0" ixz="0" iyy="0.00052872551237" iyz="0" izz="0.00017923555074"/>
    </inertial>
    <visual>
      <origin rpy="0 0 0" xyz="0 0 0"/>
      <geometry>
        <mesh filename="meshes/visual/caster_wheel_base.stl"/>
      </geometry>
      <material name="silver">
        <color rgba="0.79 0.82 0.93 1"/>
      </material>
    </visual>
    <collision>
      <origin rpy="0 0 0" xyz="0 0 0"/>
      <geometry>
        <mesh filename="meshes/collision/caster_wheel_base.stl"/>
      </geometry>
    </collision>
  </link>

  <!-- caster wheel -->
  <joint name="fl_caster_wheel_joint" type="fixed">
    <origin rpy="0 0 0" xyz="-0.0382 0 -0.094"/>
    <parent link="fl_caster_rotation_link"/>
    <child link="fl_caster_wheel_link"/>
    <axis xyz="0 1 0"/>
  </joint>
  <link name="fl_caster_wheel_link">
    <inertial>
      <mass value="1.0"/>
      <origin rpy="1.5707963267948966 0 0" xyz="0 0 0"/>
      <inertia ixx="0.001061895408575" ixy="0.0" ixz="0.0" iyy="0.001061895408575" iyz="0.0" izz="0.001953125"/>
    </inertial>
    <visual>
      <origin rpy="0 0 0" xyz="0 0 0"/>
      <geometry>
        <mesh filename="meshes/visual/wheel.stl"/>
      </geometry>
      <material name="dark_grey">
        <color rgba="0.3 0.3 0.3 1"/>
      </material>
    </visual>
    <collision>
      <origin rpy="1.5707963267948966 0 0" xyz="0 0 0"/>
      <geometry>
        <cylinder length="0.032" radius="0.0625"/>
      </geometry>
    </collision>
  </link>
 
  <!-- caster hub -->
  <joint name="fr_caster_rotation_joint" type="fixed">
    <origin rpy="0 0 0" xyz="0.341346 -0.203 0.1565"/>
    <parent link="base_link"/>
    <child link="fr_caster_rotation_link"/>
    <axis xyz="0 0 1"/>
    <dynamics damping="0.01" friction="0.0"/>
  </joint>
  <link name="fr_caster_rotation_link">
    <inertial>
      <!-- <origin xyz="0 0 -0.042500000044" rpy="${0.5 * pi} ${24 * deg_to_rad} ${1.5 * pi}" /> -->
      <origin rpy="0.41887903200000004 0 1.5707963267948966 " xyz="0 0 -0.042500000044"/>
      <mass value="0.3097539019"/>
      <inertia ixx="0.0005844517978" ixy="0" ixz="0" iyy="0.00052872551237" iyz="0" izz="0.00017923555074"/>
    </inertial>
    <visual>
      <origin rpy="0 0 0" xyz="0 0 0"/>
      <geometry>
        <mesh filename="meshes/visual/caster_wheel_base.stl"/>
      </geometry>
      <material name="silver">
        <color rgba="0.79 0.82 0.93 1"/>
      </material>
    </visual>
    <collision>
      <origin rpy="0 0 0" xyz="0 0 0"/>
      <geometry>
        <mesh filename="meshes/collision/caster_wheel_base.stl"/>
      </geometry>
    </collision>
  </link>

  <!-- caster wheel -->
  <joint name="fr_caster_wheel_joint" type="fixed">
    <origin rpy="0 0 0" xyz="-0.0382 0 -0.094"/>
    <parent link="fr_caster_rotation_link"/>
    <child link="fr_caster_wheel_link"/>
    <axis xyz="0 1 0"/>
  </joint>
  <link name="fr_caster_wheel_link">
    <inertial>
      <mass value="1.0"/>
      <origin rpy="1.5707963267948966 0 0" xyz="0 0 0"/>
      <inertia ixx="0.001061895408575" ixy="0.0" ixz="0.0" iyy="0.001061895408575" iyz="0.0" izz="0.001953125"/>
    </inertial>
    <visual>
      <origin rpy="0 0 0" xyz="0 0 0"/>
      <geometry>
        <mesh filename="meshes/visual/wheel.stl"/>
      </geometry>
      <material name="dark_grey">
        <color rgba="0.3 0.3 0.3 1"/>
      </material>
    </visual>
    <collision>
      <origin rpy="1.5707963267948966 0 0" xyz="0 0 0"/>
      <geometry>
        <cylinder length="0.032" radius="0.0625"/>
      </geometry>
    </collision>
  </link>

  <!-- caster hub -->
  <joint name="bl_caster_rotation_joint" type="fixed">
    <origin rpy="0 0 0" xyz="-0.270154 0.203 0.1565"/>
    <parent link="base_link"/>
    <child link="bl_caster_rotation_link"/>
    <axis xyz="0 0 1"/>
    <dynamics damping="0.01" friction="0.0"/>
  </joint>
  <link name="bl_caster_rotation_link">
    <inertial>
      <!-- <origin xyz="0 0 -0.042500000044" rpy="${0.5 * pi} ${24 * deg_to_rad} ${1.5 * pi}" /> -->
      <origin rpy="0.41887903200000004 0 1.5707963267948966 " xyz="0 0 -0.042500000044"/>
      <mass value="0.3097539019"/>
      <inertia ixx="0.0005844517978" ixy="0" ixz="0" iyy="0.00052872551237" iyz="0" izz="0.00017923555074"/>
    </inertial>
    <visual>
      <origin rpy="0 0 0" xyz="0 0 0"/>
      <geometry>
        <mesh filename="meshes/visual/caster_wheel_base.stl"/>
      </geometry>
      <material name="silver">
        <color rgba="0.79 0.82 0.93 1"/>
      </material>
    </visual>
    <collision>
      <origin rpy="0 0 0" xyz="0 0 0"/>
      <geometry>
        <mesh filename="meshes/collision/caster_wheel_base.stl"/>
      </geometry>
    </collision>
  </link>

  <!-- caster wheel -->
  <joint name="bl_caster_wheel_joint" type="fixed">
    <origin rpy="0 0 0" xyz="-0.0382 0 -0.094"/>
    <parent link="bl_caster_rotation_link"/>
    <child link="bl_caster_wheel_link"/>
    <axis xyz="0 1 0"/>
  </joint>
  <link name="bl_caster_wheel_link">
    <inertial>
      <mass value="1.0"/>
      <origin rpy="1.5707963267948966 0 0" xyz="0 0 0"/>
      <inertia ixx="0.001061895408575" ixy="0.0" ixz="0.0" iyy="0.001061895408575" iyz="0.0" izz="0.001953125"/>
    </inertial>
    <visual>
      <origin rpy="0 0 0" xyz="0 0 0"/>
      <geometry>
        <mesh filename="meshes/visual/wheel.stl"/>
      </geometry>
      <material name="dark_grey">
        <color rgba="0.3 0.3 0.3 1"/>
      </material>
    </visual>
    <collision>
      <origin rpy="1.5707963267948966 0 0" xyz="0 0 0"/>
      <geometry>
        <cylinder length="0.032" radius="0.0625"/>
      </geometry>
    </collision>
  </link>

  <!-- caster hub -->
  <joint name="br_caster_rotation_joint" type="fixed">
    <origin rpy="0 0 0" xyz="-0.270154 -0.203 0.1565"/>
    <parent link="base_link"/>
    <child link="br_caster_rotation_link"/>
    <axis xyz="0 0 1"/>
    <dynamics damping="0.01" friction="0.0"/>
  </joint>
  <link name="br_caster_rotation_link">
    <inertial>
      <!-- <origin xyz="0 0 -0.042500000044" rpy="${0.5 * pi} ${24 * deg_to_rad} ${1.5 * pi}" /> -->
      <origin rpy="0.41887903200000004 0 1.5707963267948966 " xyz="0 0 -0.042500000044"/>
      <mass value="0.3097539019"/>
      <inertia ixx="0.0005844517978" ixy="0" ixz="0" iyy="0.00052872551237" iyz="0" izz="0.00017923555074"/>
    </inertial>
    <visual>
      <origin rpy="0 0 0" xyz="0 0 0"/>
      <geometry>
        <mesh filename="meshes/visual/caster_wheel_base.stl"/>
      </geometry>
      <material name="silver">
        <color rgba="0.79 0.82 0.93 1"/>
      </material>
    </visual>
    <collision>
      <origin rpy="0 0 0" xyz="0 0 0"/>
      <geometry>
        <mesh filename="meshes/collision/caster_wheel_base.stl"/>
      </geometry>
    </collision>
  </link>

  <!-- caster wheel -->
  <joint name="br_caster_wheel_joint" type="fixed">
    <origin rpy="0 0 0" xyz="-0.0382 0 -0.094"/>
    <parent link="br_caster_rotation_link"/>
    <child link="br_caster_wheel_link"/>
    <axis xyz="0 1 0"/>
  </joint>
  <link name="br_caster_wheel_link">
    <inertial>
      <mass value="1.0"/>
      <origin rpy="1.5707963267948966 0 0" xyz="0 0 0"/>
      <inertia ixx="0.001061895408575" ixy="0.0" ixz="0.0" iyy="0.001061895408575" iyz="0.0" izz="0.001953125"/>
    </inertial>
    <visual>
      <origin rpy="0 0 0" xyz="0 0 0"/>
      <geometry>
        <mesh filename="meshes/visual/wheel.stl"/>
      </geometry>
      <material name="dark_grey">
        <color rgba="0.3 0.3 0.3 1"/>
      </material>
    </visual>
    <collision>
      <origin rpy="1.5707963267948966 0 0" xyz="0 0 0"/>
      <geometry>
        <cylinder length="0.032" radius="0.0625"/>
      </geometry>
    </collision>
  </link>
  
   <material name="black">
    <color rgba="0.0 0.0 0.0 1.0"/>
  </material>
  <material name="white">
    <color rgba="1.0 1.0 1.0 1.0"/>
  </material>
  <material name="orange">
    <color rgba="1.0 0.4 0.0 1.0"/>
  </material>

  <material name="dr_gray">
    <color rgba="0.490 0.490 0.486 1.0"/>
  </material>
  <material name="dr_white">
    <color rgba="0.941 0.941 0.941 1.0"/>
  </material>
  
  <joint name="surface" type="fixed">
    <parent link="base_link"/>
    <child link="base_0"/>
    <origin rpy="0 0 0" xyz="0.237646 0 0.352"/>
  </joint>
  
  <link name="base_0">
	<inertial>
	  <mass value="3.722"/>
	  <origin xyz="-1.2e-05 -6e-05 0.050723"/>
      <inertia ixx="0.011" ixy="-7.19e-06" ixz="-1.94e-06" iyy="0.011" iyz="4.9e-06" izz="0.014"/>
    </inertial>
	<visual>
      <origin rpy="0 0 0" xyz="0 0 0"/>
      <geometry>
        <mesh filename="/meshes/m0609_white/MF0609_0_0.dae" scale="0.001 0.001 0.001"/>
      </geometry>
      <material name="dr_gray"/>
    </visual>
  </link>

  <joint name="joint1" type="revolute">
    <parent link="base_0"/>
    <child link="link1"/>
    <origin rpy="0 0 0" xyz="0 0 0.1525"/>
    <axis xyz="0 0 1"/>
    <limit effort="30" lower="-2.617" upper="2.617" velocity="1.571"/>
  </joint>

  <link name="link1">
	<inertial>
	  <mass value="7.446"/>
	  <origin xyz="7e-05 0.044281 0.143327"/>
      <inertia ixx="0.039" ixy="2.1e-05" ixz="-3.61e-05" iyy="0.023" iyz="-0.003" izz="0.039"/>
    </inertial>
    <visual>
      <origin rpy="0 0 0" xyz="0 0 0"/>
      <geometry>
        <mesh filename="/meshes/m0609_white/MF0609_1_0.dae" scale="0.001 0.001 0.001"/>
      </geometry>
      <material name="dr_white"/>
    </visual>
  </link>
  
  <joint name="joint2" type="revolute">
    <parent link="link1"/>
    <child link="link2"/>
    <origin rpy="0 -1.571 -1.571" xyz="0 0.006 0"/>
    <axis xyz="0 0 1"/>
    <limit effort="30" lower="-2.617" upper="2.617" velocity="1.571"/>
  </joint>

  <link name="link2">
	<inertial>
	  <mass value="10.569"/>
	  <origin xyz="-1.6e-05 0.189372 0.418558"/>
      <inertia ixx="0.820" ixy="1.19e-05" ixz="-0.000263" iyy="0.82" iyz="-0.008" izz="0.031"/>
    </inertial>
    <visual>
      <origin rpy="0 0 0" xyz="0 0 0"/>
      <geometry>
        <mesh filename="/meshes/m0609_white/MF0609_2_0.dae" scale="0.001 0.001 0.001"/>
      </geometry>
      <material name="dr_white"/>
    </visual>
    <visual>
      <origin rpy="0 0 0" xyz="0 0 0"/>
      <geometry>     
		<mesh filename="/meshes/m0609_white/MF0609_2_1.dae" scale="0.001 0.001 0.001"/>
      </geometry>
      <material name="dr_gray">
        <color rgba="0.490 0.490 0.486 1.0"/>
      </material>
	  </visual>
    <visual>
      <origin rpy="0 0 0" xyz="0 0 0"/>
      <geometry>     
		<mesh filename="/meshes/m0609_white/MF0609_2_2.dae" scale="0.001 0.001 0.001"/>
      </geometry>
      <material name="dr_white"/>
    </visual>	
  </link>

  <joint name="joint3" type="revolute">
    <parent link="link2"/>
    <child link="link3"/>
    <origin rpy="0 0 1.571" xyz="0.411 0 0"/>
    <axis xyz="0 0 1"/>
    <limit effort="30" lower="-2.617" upper="2.617" velocity="1.571"/>
  </joint>
  
  <link name="link3">
	<inertial>
	  <mass value="3.614"/>
	  <origin xyz="6e-06 0.07917 0.781807"/>
      <inertia ixx="0.012" ixy="-4.38e-06" ixz="-1.2e-06" iyy="0.008" iyz="0.002" izz="0.011"/>
    </inertial>
    <visual>
      <origin rpy="0 0 0" xyz="0 0 0"/>
      <geometry>     
		<mesh filename="/meshes/m0609_white/MF0609_3_0.dae" scale="0.001 0.001 0.001"/>
      </geometry>
      <material name="dr_white"/>
    </visual>
  </link>

  <joint name="joint4" type="revolute">
    <parent link="link3"/>
    <child link="link4"/>
    <origin rpy="1.571 0 0" xyz="0 -0.368 0"/>
    <axis xyz="0 0 1"/>
    <limit effort="30" lower="-2.617" upper="2.617" velocity="1.571"/>
  </joint>
  
  <link name="link4">
	<inertial>
	  <mass value="3.785"/>
	  <origin xyz="-2.1e-05 0.12337 1.148"/>
      <inertia ixx="0.177" ixy="-2.34e-06" ixz="-4.92e-06" iyy="0.161" iyz="-0.05" izz="0.022"/>
    </inertial>
    <visual>
      <origin rpy="0 0 0" xyz="0 0 0"/>
      <geometry>     
		<mesh filename="/meshes/m0609_white/MF0609_4_0.dae" scale="0.001 0.001 0.001"/>
      </geometry>
      <material name="dr_white"/>
    </visual>
    <visual>
      <origin rpy="0 0 0" xyz="0 0 0"/>
      <geometry>     
		<mesh filename="/meshes/m0609_white/MF0609_4_1.dae" scale="0.001 0.001 0.001"/>
      </geometry>
      <material name="dr_white">
        <color rgba="0.941 0.941 0.941 1.0"/>
      </material>
    </visual>
  </link>

  <joint name="joint5" type="revolute">
    <parent link="link4"/>
    <child link="link5"/>
    <origin rpy="-1.571 0 0" xyz="0 0 0"/>
    <axis xyz="0 0 1"/>
    <limit effort="30" lower="-2.617" upper="2.617" velocity="1.571"/>
  </joint>
  
  <link name="link5">
	<inertial>
	  <mass value="2.598"/>
	  <origin xyz="-1.7e-05 0.06662 1.33103"/>
      <inertia ixx="0.007" ixy="-4.93e-06" ixz="-5.57e-06" iyy="0.004" iyz="-6.64e-05" izz="0.007"/>
    </inertial>
    <visual>
      <origin rpy="0 0 0" xyz="0 0 0"/>
      <geometry>     
		<mesh filename="/meshes/m0609_white/MF0609_5_0.dae" scale="0.001 0.001 0.001"/>
      </geometry>
      <material name="dr_white"/>
    </visual>
  </link>

  <joint name="joint6" type="revolute">
    <parent link="link5"/>
    <child link="link6"/>
    <origin rpy="1.571 0 0" xyz="0 -0.121 0"/>
    <axis xyz="0 0 1"/>
    <limit effort="30" lower="-2.617" upper="2.617" velocity="1.571"/>
  </joint>
  
  <link name="link6">
	<inertial>
	  <mass value="1.128"/>
	  <origin xyz="-0.000174 0.034708 1.40022"/>
      <inertia ixx="0.001" ixy="-2.79e-06" ixz="5.78e-06" iyy="0.001" iyz="-6.67e-06" izz="0.001"/>
    </inertial>
    <visual>
      <origin rpy="0 0 0" xyz="0 0 0"/>
      <geometry>     
		<mesh filename="/meshes/m0609_white/MF0609_6_0.dae" scale="0.001 0.001 0.001"/>
      </geometry>
      <material name="dr_gray"/>
    </visual>
  </link>
  <joint name="endeffector" type="fixed">
    <origin rpy="0.0 0.0 0.0" xyz="0.0 0.0 0.0"/>
    <parent link="link6"/>
    <child link="tool0"/>
  </joint>
  <link name="tool0">
      <inertial>
          <mass value="0.000001" />
          <origin xyz="0.0 0.0 0.0" rpy="0 0 0" />
          <inertia ixx="0.000001" ixy="0" ixz="0" iyy="0.000001" iyz="0" izz="0.000001" />
      </inertial>
  </link>
  
  
  <!-- instead of the controller_plugin_gazebo, you can use the diffdrive controller like this:
    <xacro:diff_controller_plugin_gazebo prefix=""
      left_wheel_joint="left_wheel_joint"
      right_wheel_joint="right_wheel_joint"
      wheel_separation="${2*mir_100_act_wheel_dy}"
      wheel_radius="${mir_100_act_wheel_radius}"/>
  -->
</robot>

