<?xml version="1.0" ?>

<robot name="m0609">

  <material name="dark_grey">
    <color rgba="0.2 0.2 0.2 1.0"/>
  </material>
  <material name="light_grey">
    <color rgba="0.4 0.4 0.4 1.0"/>
  </material>
  <material name="red">
    <color rgba="0.8 0.0 0.0 1.0"/>
  </material>

  <material name="yellow">
    <color rgba="0.8 0.8 0.0 1.0"/>
  </material>
  
   <material name="black">
    <color rgba="0.0 0.0 0.0 1.0"/>
  </material>
  <material name="white">
    <color rgba="1.0 1.0 1.0 1.0"/>
  </material>
  <material name="orange">
    <color rgba="1.0 0.4 0.0 1.0"/>
  </material>
  <material name="dr_gray">
    <color rgba="0.490 0.490 0.486 1.0"/>
  </material>
  <material name="dr_white">
    <color rgba="0.941 0.941 0.941 1.0"/>
  </material>

  <!-- M0609 URDF -->
  <link name="base">
        <inertial>
          <mass value="0.000001" />
          <origin xyz="0.0 0.0 0.0" rpy="0 0 0" />
          <inertia ixx="0.000001" ixy="0" ixz="0" iyy="0.000001" iyz="0" izz="0.000001" />
      </inertial>
  </link>
  
  <joint name="fixed" type="fixed">
    <parent link="base"/>
    <child link="base_0"/>
  </joint>
  
  <link name="base_0">
	<inertial>
	  <mass value="2.953"/>
	  <origin xyz="-2.8e-05 -0.006045    0.038403"/>
      <inertia ixx="0.017789" ixy="-7.4356e-06" ixz="3.0378e-06" iyy="0.011135"
					iyz="-0.00029038"
					izz="0.020054"/>
    </inertial>
	<visual>
      <origin rpy="0 0 0" xyz="0 0 0"/>
      <geometry>
        <mesh filename="package://dsr_description/meshes/m0609/MF0609_0_0.dae" scale="0.001 0.001 0.001"/>
      </geometry>
      <material name="dr_gray"/>
    </visual>
  </link>

  <joint name="joint1" type="revolute">
    <parent link="base_0"/>
    <child link="link1"/>
    <origin rpy="0 0 0" xyz="0 0 0.135"/>
    <axis xyz="0 0 1"/>
    <limit effort="30" lower="-2.617" upper="2.617" velocity="1.571"/>
  </joint>
  <transmission name="trans_joint1">
    <type>transmission_interface/SimpleTransmission</type>
    <joint name="joint1">
      <hardwareInterface>hardware_interface/EffortJointInterface</hardwareInterface>
    </joint>
    <actuator name="motor_joint1">
      <hardwareInterface>hardware_interface/EffortJointInterface</hardwareInterface>
      <mechanicalReduction>1</mechanicalReduction>
    </actuator>
  </transmission>

  <link name="link1">
	<inertial>
		<mass value="4.935"/>
		<origin xyz="7.2e-05    0.036227   -0.003417"/>
		<inertia ixx="0.026195" ixy="2.3904e-05" ixz="-1.3319e-05" iyy="0.016899"
			iyz="-0.00071987"
			izz="0.022944"/>
	</inertial>
    <visual>
      <origin rpy="0 0 0" xyz="0 0 0"/>
      <geometry>
        <mesh filename="package://dsr_description/meshes/m0609/MF0609_1_0.dae" scale="0.001 0.001 0.001"/>
      </geometry>
      <material name="dr_white"/>
    </visual>
  </link>
  
  <joint name="joint2" type="revolute">
    <parent link="link1"/>
    <child link="link2"/>
    <origin rpy="0 -1.571 -1.571" xyz="0 0.0062 0"/>
    <axis xyz="0 0 1"/>
    <limit effort="30" lower="-2.617" upper="2.617" velocity="1.571"/>
  </joint>
  <transmission name="trans_joint2">
    <type>transmission_interface/SimpleTransmission</type>
    <joint name="joint2">
      <hardwareInterface>hardware_interface/EffortJointInterface</hardwareInterface>
    </joint>
    <actuator name="motor_joint2">
      <hardwareInterface>hardware_interface/EffortJointInterface</hardwareInterface>
      <mechanicalReduction>1</mechanicalReduction>
    </actuator>
  </transmission>

  <link name="link2">
	<inertial>
		<mass value="8.363"/>
		<origin xyz="0.20447     2.6e-05     0.16005"/>
		<inertia ixx="0.026743" ixy="-0.00019461" ixz="-0.00058734" iyy="0.30084"
			iyz="-6.7892e-06"
			izz="0.29898"/>
	</inertial>
    <visual>
      <origin rpy="0 0 0" xyz="0 0 0"/>
      <geometry>
        <mesh filename="package://dsr_description/meshes/m0609/MF0609_2_0.dae" scale="0.001 0.001 0.001"/>
      </geometry>
      <material name="dr_white"/>
    </visual>
    <visual>
      <origin rpy="0 0 0" xyz="0 0 0"/>
      <geometry>     
		<mesh filename="package://dsr_description/meshes/m0609/MF0609_2_1.dae" scale="0.001 0.001 0.001"/>
      </geometry>
      <material name="dr_gray">
        <color rgba="0.490 0.490 0.486 1.0"/>
      </material>
	  </visual>
    <visual>
      <origin rpy="0 0 0" xyz="0 0 0"/>
      <geometry>     
		<mesh filename="package://dsr_description/meshes/m0609/MF0609_2_2.dae" scale="0.001 0.001 0.001"/>
      </geometry>
      <material name="dr_white"/>
    </visual>	
  </link>

  <joint name="joint3" type="revolute">
    <parent link="link2"/>
    <child link="link3"/>
    <origin rpy="0 0 1.571" xyz="0.411 0 0"/>
    <axis xyz="0 0 1"/>
    <limit effort="30" lower="-2.617" upper="2.617" velocity="1.571"/>
  </joint>
  <transmission name="trans_joint3">
    <type>transmission_interface/SimpleTransmission</type>
    <joint name="joint3">
      <hardwareInterface>hardware_interface/EffortJointInterface</hardwareInterface>
    </joint>
    <actuator name="motor_joint3">
      <hardwareInterface>hardware_interface/EffortJointInterface</hardwareInterface>
      <mechanicalReduction>1</mechanicalReduction>
    </actuator>
  </transmission>
  
  <link name="link3">
	<inertial>
		<mass value="3.583"/>
		<origin xyz="-2.2e-05   -0.006867    0.043445"/>
		<inertia ixx="0.018342" ixy="1.1302e-05" ixz="-4.5308e-06" iyy="0.018239"
			iyz="-0.00099247"
			izz="0.01326"/>
	</inertial>
    <visual>
      <origin rpy="0 0 0" xyz="0 0 0"/>
      <geometry>     
		<mesh filename="package://dsr_description/meshes/m0609/MF0609_3_0.dae" scale="0.001 0.001 0.001"/>
      </geometry>
      <material name="dr_white"/>
    </visual>
  </link>

  <joint name="joint4" type="revolute">
    <parent link="link3"/>
    <child link="link4"/>
    <origin rpy="1.571 0 0" xyz="0 -0.368 0"/>
    <axis xyz="0 0 1"/>
    <limit effort="30" lower="-2.617" upper="2.617" velocity="1.571"/>
  </joint>
  <transmission name="trans_joint4">
    <type>transmission_interface/SimpleTransmission</type>
    <joint name="joint4">
      <hardwareInterface>hardware_interface/EffortJointInterface</hardwareInterface>
    </joint>
    <actuator name="motor_joint4">
      <hardwareInterface>hardware_interface/EffortJointInterface</hardwareInterface>
      <mechanicalReduction>1</mechanicalReduction>
    </actuator>
  </transmission>
  
  <link name="link4">
	<inertial>
		<mass value="3.433"/>
		<origin xyz="4e-05    0.097079    -0.10981"/>
		<inertia ixx="0.08035" ixy="-4.6119e-06" ixz="-8.1798e-06" iyy="0.066005"
			iyz="-0.028996"
			izz="0.029763"/>
	</inertial>
    <visual>
      <origin rpy="0 0 0" xyz="0 0 0"/>
      <geometry>     
		<mesh filename="package://dsr_description/meshes/m0609/MF0609_4_0.dae" scale="0.001 0.001 0.001"/>
      </geometry>
      <material name="dr_white"/>
    </visual>
    <visual>
      <origin rpy="0 0 0" xyz="0 0 0"/>
      <geometry>     
		<mesh filename="package://dsr_description/meshes/m0609/MF0609_4_1.dae" scale="0.001 0.001 0.001"/>
      </geometry>
      <material name="dr_white">
        <color rgba="0.941 0.941 0.941 1.0"/>
      </material>
    </visual>
  </link>

  <joint name="joint5" type="revolute">
    <parent link="link4"/>
    <child link="link5"/>
    <origin rpy="-1.571 0 0" xyz="0 0 0"/>
    <axis xyz="0 0 1"/>
    <limit effort="30" lower="-2.617" upper="2.617" velocity="1.571"/>
  </joint>
  <transmission name="trans_joint5">
    <type>transmission_interface/SimpleTransmission</type>
    <joint name="joint5">
      <hardwareInterface>hardware_interface/EffortJointInterface</hardwareInterface>
    </joint>
    <actuator name="motor_joint5">
      <hardwareInterface>hardware_interface/EffortJointInterface</hardwareInterface>
      <mechanicalReduction>1</mechanicalReduction>
    </actuator>
  </transmission>
  
  <link name="link5">
	<inertial>
		<mass value="2.598"/>
		<origin xyz="-6.8e-05    0.003827    0.031969"/>
		<inertia ixx="0.014275" ixy="2.2026e-05" ixz="3.3017e-06" iyy="0.012569"
			iyz="0.00045077"
			izz="0.0085318"/>
	</inertial>
    <visual>
      <origin rpy="0 0 0" xyz="0 0 0"/>
      <geometry>     
		<mesh filename="package://dsr_description/meshes/m0609/MF0609_5_0.dae" scale="0.001 0.001 0.001"/>
      </geometry>
      <material name="dr_white"/>
    </visual>
  </link>

  <joint name="joint6" type="revolute">
    <parent link="link5"/>
    <child link="link6"/>
    <origin rpy="1.571 0 0" xyz="0 -0.121 0"/>
    <axis xyz="0 0 1"/>
    <limit effort="30" lower="-2.617" upper="2.617" velocity="1.571"/>
  </joint>
  <transmission name="trans_joint6">
    <type>transmission_interface/SimpleTransmission</type>
    <joint name="joint6">
      <hardwareInterface>hardware_interface/EffortJointInterface</hardwareInterface>
    </joint>
    <actuator name="motor_joint6">
      <hardwareInterface>hardware_interface/EffortJointInterface</hardwareInterface>
      <mechanicalReduction>1</mechanicalReduction>
    </actuator>
  </transmission>
  
  <link name="link6">
	<inertial>
		<mass value="1.128"/>
		<origin xyz="-3e-05    -4.5e-05     -0.0539"/>
		<inertia ixx="0.0080226" ixy="1.371e-06" ixz="6.3578e-06" iyy="0.0053992"
			iyz="7.4676e-06"
			izz="0.0053912"/>
	</inertial>
    <visual>
      <origin rpy="0 0 0" xyz="0 0 0"/>
      <geometry>     
		<mesh filename="package://dsr_description/meshes/m0609/MF0609_6_0.dae" scale="0.001 0.001 0.001"/>
      </geometry>
      <material name="dr_gray"/>
    </visual>
  </link>

  <!-- ROS-Industrial 'flange' frame: attachment point for EEF models -->
  <link name="m0609_arm_flange">
        <inertial>
          <mass value="0.74" />
          <origin xyz="0.0 0.0 0.11" rpy="0 0 0" />
          <inertia ixx="0.0001" ixy="0" ixz="0" iyy="0.0001" iyz="0" izz="0.0001" />
      </inertial>
      <visual>
          <origin rpy="0 0 0" xyz="0 0 0"/>
          <geometry>     
		<mesh filename="package://dsr_description/meshes/m0609/peg_sim.dae" scale="0.001 0.001 0.001"/>
          </geometry>
          <material name="dr_gray"/>
    </visual>
  </link>
  <joint name="m0609_arm_flange_joint" type="fixed">
    <parent link="link6"/>
    <child link="m0609_arm_flange"/>
    <origin rpy="0 0 0" xyz="0 0 -0.000"/>
  </joint>
  <!-- ROS-Industrial 'tool0' frame: all-zeros tool frame -->
  <link name="m0609_arm_tool0">
      <inertial>
          <mass value="0.000001" />
          <origin xyz="0.0 0.0 0.0" rpy="0 0 0" />
          <inertia ixx="0.000001" ixy="0" ixz="0" iyy="0.000001" iyz="0" izz="0.000001" />
      </inertial>
  </link>
  <joint name="m0609_arm_flange_tool0" type="fixed">
    <!-- default toolframe: X+ left, Y+ up, Z+ front -->
    <origin rpy="0 -1.7453 0" xyz="-0.012 0 0.2205"/>
    <parent link="m0609_arm_flange"/>
    <child link="m0609_arm_tool0"/>
  </joint>
</robot>
