<?xml version="1.0" ?>
<!-- =================================================================================== -->
<!-- |    This document was autogenerated by xacro from mmo_500.urdf.xacro             | -->
<!-- |    EDITING THIS FILE BY HAND IS NOT RECOMMENDED                                 | -->
<!-- =================================================================================== -->
<robot name="mmo_500" xmlns:xacro="http://www.ros.org/wiki/xacro">
  <gazebo reference="base_link">
    <gravity>true</gravity>
    <self_collide>false</self_collide>
  </gazebo>
  <gazebo reference="mpo_500_omni_wheel_front_left_link">
    <gravity>true</gravity>
    <self_collide>false</self_collide>
  </gazebo>
  <gazebo reference="mpo_500_omni_wheel_front_right_link">
    <gravity>true</gravity>
    <self_collide>false</self_collide>
  </gazebo>
  <gazebo reference="mpo_500_omni_wheel_back_left_link">
    <gravity>true</gravity>
    <self_collide>false</self_collide>
  </gazebo>
  <gazebo reference="mpo_500_omni_wheel_back_right_link">
    <gravity>true</gravity>
    <self_collide>false</self_collide>
  </gazebo>
  <!-- Lidar sensors -->
  <gazebo reference="lidar_1_link">
    <sensor name="lidar_1_sensor" type="ray">
      <pose>0 0 0 0 0 0</pose>
      <visualize>false</visualize>
      <update_rate>40</update_rate>
      <ray>
        <scan>
          <horizontal>
            <samples>720</samples>
            <resolution>1</resolution>
            <min_angle>-1.48353</min_angle>
            <max_angle>1.48353</max_angle>
          </horizontal>
        </scan>
        <range>
          <min>0.10</min>
          <max>30.0</max>
          <resolution>0.05</resolution>
        </range>
        <noise>
          <type>gaussian</type>
          <!-- Noise parameters based on published spec for Hokuyo laser
                   achieving "+-30mm" accuracy at range < 10m.  A mean of 0.0m and
                   stddev of 0.01m will put 99.7% of samples within 0.03m of the true
                   reading. -->
          <mean>0.0</mean>
          <stddev>0.01</stddev>
        </noise>
      </ray>
      <plugin filename="libgazebo_ros_laser.so" name="lidar_1">
        <topicName>lidar_1/scan_filtered</topicName>
        <frameName>lidar_1_link</frameName>
      </plugin>
    </sensor>
  </gazebo>
  <gazebo reference="lidar_2_link">
    <sensor name="lidar_2_sensor" type="ray">
      <pose>0 0 0 0 0 0</pose>
      <visualize>false</visualize>
      <update_rate>40</update_rate>
      <ray>
        <scan>
          <horizontal>
            <samples>720</samples>
            <resolution>1</resolution>
            <min_angle>-1.48353</min_angle>
            <max_angle>1.48353</max_angle>
          </horizontal>
        </scan>
        <range>
          <min>0.10</min>
          <max>30.0</max>
          <resolution>0.05</resolution>
        </range>
        <noise>
          <type>gaussian</type>
          <!-- Noise parameters based on published spec for Hokuyo laser
                   achieving "+-30mm" accuracy at range < 10m.  A mean of 0.0m and
                   stddev of 0.01m will put 99.7% of samples within 0.03m of the true
                   reading. -->
          <mean>0.0</mean>
          <stddev>0.01</stddev>
        </noise>
      </ray>
      <plugin filename="libgazebo_ros_laser.so" name="lidar_2">
        <topicName>lidar_2/scan_filtered</topicName>
        <frameName>lidar_2_link</frameName>
      </plugin>
    </sensor>
  </gazebo>
  <!-- IMU sensor -->
  <gazebo reference="imu_link">
    <gravity>true</gravity>
    <sensor name="imu_sensor" type="imu">
      <always_on>true</always_on>
      <update_rate>100</update_rate>
      <visualize>true</visualize>
      <topic>__default_topic__</topic>
      <plugin filename="libgazebo_ros_imu_sensor.so" name="imu_plugin">
        <topicName>imu</topicName>
        <bodyName>imu_link</bodyName>
        <updateRateHZ>10.0</updateRateHZ>
        <gaussianNoise>0.0</gaussianNoise>
        <xyzOffset>0 0 0</xyzOffset>
        <rpyOffset>0 0 0</rpyOffset>
        <frameName>imu_link</frameName>
      </plugin>
      <pose>0 0 0 0 0 0</pose>
    </sensor>
  </gazebo>
  <!-- Ultrasonic sensors -->
  <gazebo reference="us_1_link">
    <!-- Visuals / Collisions omitted for this example -->
    <sensor name="range" type="ray">
      <ray>
        <scan>
          <horizontal>
            <samples>1</samples>
            <resolution>1.0</resolution>
            <min_angle>-0.01</min_angle>
            <max_angle>0.01</max_angle>
          </horizontal>
          <vertical>
            <samples>1</samples>
            <resolution>1</resolution>
            <min_angle>-0.01</min_angle>
            <max_angle>0.01</max_angle>
          </vertical>
        </scan>
        <range>
          <min>0.01</min>
          <max>3.75</max>
          <resolution>0.02</resolution>
        </range>
      </ray>
      <plugin filename="libgazebo_ros_range.so" name="libgazebo_ros_range">
        <gaussianNoise>0.005</gaussianNoise>
        <alwaysOn>true</alwaysOn>
        <updateRate>50</updateRate>
        <topicName>us_sensor</topicName>
        <frameName>us_1_link</frameName>
        <radiation>SONAR</radiation>
        <fov>0.2967</fov>
      </plugin>
    </sensor>
  </gazebo>
  <!-- camera -->
  <gazebo reference="camera_link">
    <sensor name="camera1" type="camera">
      <update_rate>30.0</update_rate>
      <camera name="head">
        <horizontal_fov>1.3962634</horizontal_fov>
        <image>
          <width>800</width>
          <height>800</height>
          <format>R8G8B8</format>
        </image>
        <clip>
          <near>0.02</near>
          <far>300</far>
        </clip>
        <noise>
          <type>gaussian</type>
          <!-- Noise is sampled independently per pixel on each frame.
               That pixel's noise value is added to each of its color
               channels, which at that point lie in the range [0,1]. -->
          <mean>0.0</mean>
          <stddev>0.007</stddev>
        </noise>
      </camera>
      <plugin filename="libgazebo_ros_camera.so" name="camera_controller">
        <alwaysOn>true</alwaysOn>
        <updateRate>0.0</updateRate>
        <cameraName>camera1</cameraName>
        <imageTopicName>image_raw</imageTopicName>
        <cameraInfoTopicName>camera_info</cameraInfoTopicName>
        <frameName>camera_link</frameName>
        <hackBaseline>0.07</hackBaseline>
        <distortionK1>0.0</distortionK1>
        <distortionK2>0.0</distortionK2>
        <distortionK3>0.0</distortionK3>
        <distortionT1>0.0</distortionT1>
        <distortionT2>0.0</distortionT2>
      </plugin>
    </sensor>
  </gazebo>
  <gazebo>
    <plugin filename="libgazebo_ros_planar_move.so" name="mpo_500_controller">
      <commandTopic>cmd_vel</commandTopic>
      <odometryTopic>odom</odometryTopic>
      <odometryFrame>odom</odometryFrame>
      <odometryRate>20.0</odometryRate>
      <robotBaseFrame>base_link</robotBaseFrame>
    </plugin>
  </gazebo>
  <gazebo>
    <plugin filename="libgazebo_ros_control.so" name="ros_control">
      <legacyModeNS>false</legacyModeNS>
      <robotSimType>gazebo_ros_control/DefaultRobotHWSim</robotSimType>
    </plugin>
  </gazebo>
  <gazebo>
    <plugin filename="libgazebo_ros_moveit_planning_scene.so" name="gazebo_ros_moveit_planning_scene">
      <topicName>/planning_scene</topicName>
      <sceneName>laboratory</sceneName>
      <robotName>mmo_500</robotName>
      <updatePeriod>0.5</updatePeriod>
    </plugin>
  </gazebo>
  <gazebo>
    <plugin filename="libgazebo_grasp_fix.so" name="gazebo_grasp_fix">
      <arm>
        <arm_name>arm</arm_name>
        <palm_link>wrist_3_link</palm_link>
        <!-- <gripper_link>H1_F1_link_1</gripper_link>
           <gripper_link>H1_F2_link_1</gripper_link>
           <gripper_link>H1_F3_link_1</gripper_link> -->
        <gripper_link>H1_F1_link_2</gripper_link>
        <gripper_link>H1_F2_link_2</gripper_link>
        <gripper_link>H1_F3_link_2</gripper_link>
      </arm>
      <forces_angle_tolerance>90</forces_angle_tolerance>
      <update_rate>4</update_rate>
      <grip_count_threshold>4</grip_count_threshold>
      <max_grip_count>20</max_grip_count>
      <release_tolerance>0.003</release_tolerance>
      <disable_collisions_on_attach>false</disable_collisions_on_attach>
      <contact_topic>__default_topic__</contact_topic>
    </plugin>
  </gazebo>
  <!-- SENSORS -->
  <!-- Sick-S300 -->
  <!-- <xacro:include filename="$(find neo_simulation)/robots/mmo_500/xacros/sick_S300.xacro" /> -->
  <!-- Ultrasonics, cameras and IMU's -->
  <!-- <xacro:include filename="$(find neo_simulation)/robots/mmo_500/urdf/xacros/imu.xacro" />

  <xacro:include filename="$(find neo_simulation)/robots/mmo_500/urdf/xacros/ultrasonic.xacro" /> -->
  <!-- <xacro:include filename="$(find neo_simulation)/robots/mmo_500/urdf/xacros/camera.xacro" />  -->
  <!-- measured from model -->
  <!-- Pilz -->
  <!-- <xacro:include filename="$(find neo_simulation)/robots/mmo_500/urdf/prbt_macro.xacro" /> -->
  <link name="base_link"/>
  <joint name="base_footprint_joint" type="fixed">
    <origin rpy="0 0 0" xyz="0 0 0"/>
    <axis xyz="0 0 -1"/>
    <!-- <limit effort="1000.0" lower="-1e+16" upper="1e+16" velocity="3.5"/> -->
    <joint_properties damping="1" friction="1"/>
    <parent link="base_link"/>
    <child link="base_footprint"/>
  </joint>
  <link name="base_footprint">
    <inertial>
      <mass value="64"/>
      <origin xyz="0 0.0 0.0"/>
      <inertia ixx="2.8" ixy="0.0" ixz="0.0" iyy="2.8" iyz="0.0" izz="2.8"/>
    </inertial>
    <visual>
      <origin rpy="-1.571 0 1.571" xyz="0. 0. 0"/>
      <geometry>
        <mesh filename="package://neo_simulation/robots/mmo_500/meshes/MPO-500-BODY.dae" scale="0.001 0.001 0.001"/>
      </geometry>
    </visual>
    <collision>
      <origin rpy="-1.571 0 1.571" xyz="0. 0. 0.0"/>
      <geometry>
        <!--<box size="0.68 0.41 0.25"/> -->
        <mesh filename="package://neo_simulation/robots/mmo_500/meshes/MPO-500-BODY.dae" scale="0.001 0.001 0.001"/>
      </geometry>
    </collision>
  </link>
  <joint name="mpo_500_omni_wheel_front_left_joint" type="fixed">
    <origin rpy="0 0 0" xyz="0.25 0.28 0.13"/>
    <axis xyz="0 1 0"/>
    <joint_properties damping="100" friction="100"/>
    <parent link="base_footprint"/>
    <child link="mpo_500_omni_wheel_front_left_link"/>
  </joint>
  <link name="mpo_500_omni_wheel_front_left_link" type="wheel">
    <inertial>
      <mass value="4.2"/>
      <origin rpy="0 0 0" xyz="0 0 0"/>
      <inertia ixx="0.0338" ixy="0.0" ixz="0.0" iyy="0.0338" iyz="0.0" izz="0.0338"/>
    </inertial>
    <visual>
      <origin rpy="0 0 0" xyz="0 0 0"/>
      <geometry>
        <mesh filename="package://neo_simulation/robots/mmo_500/meshes/MPO-500-WHEEL.dae" scale="0.001 0.001 0.001"/>
      </geometry>
    </visual>
    <collision>
      <origin rpy="1.57 0 0" xyz="0 0 0"/>
      <geometry>
        <sphere radius="0.127"/>
      </geometry>
    </collision>
  </link>
  <gazebo reference="mpo_500_omni_wheel_front_left_link">
    <mu1>0.045</mu1>
    <mu2>0.045</mu2>
  </gazebo>
  <joint name="mpo_500_omni_wheel_front_right_joint" type="fixed">
    <origin rpy="0 0 3.14" xyz="0.25 -0.28 0.13"/>
    <axis xyz="0 1 0"/>
    <joint_properties damping="100" friction="100"/>
    <parent link="base_footprint"/>
    <child link="mpo_500_omni_wheel_front_right_link"/>
  </joint>
  <link name="mpo_500_omni_wheel_front_right_link" type="wheel">
    <inertial>
      <mass value="4.2"/>
      <origin rpy="0 0 0" xyz="0 0 0"/>
      <inertia ixx="0.0338" ixy="0.0" ixz="0.0" iyy="0.0338" iyz="0.0" izz="0.0338"/>
    </inertial>
    <visual>
      <origin rpy="0 0 0" xyz="0 0 0"/>
      <geometry>
        <mesh filename="package://neo_simulation/robots/mmo_500/meshes/MPO-500-WHEEL.dae" scale="0.001 0.001 0.001"/>
      </geometry>
    </visual>
    <collision>
      <origin rpy="1.57 0 0" xyz="0 0 0"/>
      <geometry>
        <sphere radius="0.127"/>
      </geometry>
    </collision>
  </link>
  <gazebo reference="mpo_500_omni_wheel_front_right_link">
    <mu1>0.045</mu1>
    <mu2>0.045</mu2>
  </gazebo>
  <joint name="mpo_500_omni_wheel_back_left_joint" type="fixed">
    <origin rpy="0 0 0" xyz="-0.25 0.28 0.13"/>
    <axis xyz="0 1 0"/>
    <joint_properties damping="100" friction="100"/>
    <parent link="base_footprint"/>
    <child link="mpo_500_omni_wheel_back_left_link"/>
  </joint>
  <link name="mpo_500_omni_wheel_back_left_link" type="wheel">
    <inertial>
      <mass value="4.2"/>
      <origin rpy="0 0 0" xyz="0 0 0"/>
      <inertia ixx="0.0338" ixy="0.0" ixz="0.0" iyy="0.0338" iyz="0.0" izz="0.0338"/>
    </inertial>
    <visual>
      <origin rpy="0 0 0" xyz="0 0 0"/>
      <geometry>
        <mesh filename="package://neo_simulation/robots/mmo_500/meshes/MPO-500-WHEEL.dae" scale="0.001 0.001 0.001"/>
      </geometry>
    </visual>
    <collision>
      <origin rpy="1.57 0 0" xyz="0 0 0"/>
      <geometry>
        <sphere radius="0.127"/>
      </geometry>
    </collision>
  </link>
  <gazebo reference="mpo_500_omni_wheel_back_left_link">
    <mu1>0.045</mu1>
    <mu2>0.045</mu2>
  </gazebo>
  <joint name="mpo_500_omni_wheel_back_right_joint" type="fixed">
    <origin rpy="0 0 3.14" xyz="-0.25 -0.28 0.13"/>
    <axis xyz="0 1 0"/>
    <joint_properties damping="100" friction="100"/>
    <parent link="base_footprint"/>
    <child link="mpo_500_omni_wheel_back_right_link"/>
  </joint>
  <link name="mpo_500_omni_wheel_back_right_link" type="wheel">
    <inertial>
      <mass value="4.2"/>
      <origin rpy="0 0 0" xyz="0 0 0"/>
      <inertia ixx="0.0338" ixy="0.0" ixz="0.0" iyy="0.0338" iyz="0.0" izz="0.0338"/>
    </inertial>
    <visual>
      <origin rpy="0 0 0" xyz="0 0 0"/>
      <geometry>
        <mesh filename="package://neo_simulation/robots/mmo_500/meshes/MPO-500-WHEEL.dae" scale="0.001 0.001 0.001"/>
      </geometry>
    </visual>
    <collision>
      <origin rpy="1.57 0 0" xyz="0 0 0"/>
      <geometry>
        <sphere radius="0.127"/>
      </geometry>
    </collision>
  </link>
  <gazebo reference="mpo_500_omni_wheel_back_right_link">
    <mu1>0.045</mu1>
    <mu2>0.045</mu2>
  </gazebo>
  <joint name="lidar_1_joint" type="fixed">
    <axis xyz="0 1 0"/>
    <origin rpy="0 0 0" xyz="0.442 0 0.372"/>
    <parent link="base_link"/>
    <child link="lidar_1_link"/>
  </joint>
  <link name="lidar_1_link" type="laser">
    <inertial>
      <mass value="0.0001"/>
      <origin rpy="0 0 0" xyz="0 0 0"/>
      <inertia ixx="0.0001" ixy="0" ixz="0" iyy="0.000001" iyz="0" izz="0.0001"/>
    </inertial>
    <visual>
      <origin rpy="1.57 0 0" xyz="0 0 -0.06"/>
      <geometry>
        <mesh filename="package://neo_simulation/robots/mmo_500/meshes/SICK-MICROSCAN3.dae" scale="0.001 0.001 0.001"/>
      </geometry>
    </visual>
    <collision>
      <origin rpy="1.57 0 0" xyz="0 0 -0.06"/>
      <geometry>
        <mesh filename="package://neo_simulation/robots/mmo_500/meshes/SICK-MICROSCAN3.dae" scale="0.001 0.001 0.001"/>
      </geometry>
    </collision>
  </link>
  <joint name="lidar_2_joint" type="fixed">
    <axis xyz="0 1 0"/>
    <origin rpy="0 0 3.14" xyz="-0.442 0 0.372"/>
    <parent link="base_link"/>
    <child link="lidar_2_link"/>
  </joint>
  <link name="lidar_2_link" type="laser">
    <inertial>
      <mass value="0.0001"/>
      <origin rpy="0 0 0" xyz="0 0 0"/>
      <inertia ixx="0.0001" ixy="0" ixz="0" iyy="0.000001" iyz="0" izz="0.0001"/>
    </inertial>
    <visual>
      <origin rpy="1.57 0 0" xyz="0 0 -0.06"/>
      <geometry>
        <mesh filename="package://neo_simulation/robots/mmo_500/meshes/SICK-MICROSCAN3.dae" scale="0.001 0.001 0.001"/>
      </geometry>
    </visual>
    <collision>
      <origin rpy="1.57 0 0" xyz="0 0 -0.06"/>
      <geometry>
        <mesh filename="package://neo_simulation/robots/mmo_500/meshes/SICK-MICROSCAN3.dae" scale="0.001 0.001 0.001"/>
      </geometry>
    </collision>
  </link>
  <!--+++++++++++++++++++ IMU ++++++++++++++++++++++++-->
  <!-- Comment or uncomment based on your requirement -->
  <!--   <xacro:imu name="imu_1" parent="base_link">
    <origin xyz="0.100 0 0.300" rpy="0 0 3.14" />
  </xacro:imu> -->
  <!--+++++++++++++++++++ Ultra Sonic ++++++++++++++++++++++++-->
  <!-- Comment or uncomment based on your requirement -->
  <!-- SENSOR 1 -->
  <!-- xacro:us_sensor name="us_1" parent="base_link">
    <origin xyz="0.100 0 0.300" rpy="0 3.14 3.14" />
  </xacro:us_sensor-->
  <!-- SENSOR 2 -->
  <!-- xacro:us_sensor name="us_2" parent="base_link">
    <origin xyz="0.110 0 0.300" rpy="0 3.14 3.14" />
  </xacro:us_sensor-->
  <!-- SENSOR 3 -->
  <!-- xacro:us_sensor name="us_3" parent="base_link">
    <origin xyz="0.120 0 0.300" rpy="0 3.14 3.14" />
  </xacro:us_sensor-->
  <!-- SENSOR 4 -->
  <!-- xacro:us_sensor name="us_4" parent="base_link">
    <origin xyz="0.130 0 0.300" rpy="0 3.14 3.14" />
  </xacro:us_sensor-->
  <!-- SENSOR 5 -->
  <!-- xacro:us_sensor name="us_5" parent="base_link">
    <origin xyz="0.140 0 0.300" rpy="0 3.14 3.14" />
  </xacro:us_sensor-->
  <!-- SENSOR 6 -->
  <!-- xacro:us_sensor name="us_6" parent="base_link">
    <origin xyz="0.150 0 0.300" rpy="0 3.14 3.14" />
  </xacro:us_sensor-->
  <!-- SENSOR 7 -->
  <!-- xacro:us_sensor name="us_7" parent="base_link">
    <origin xyz="0.160 0 0.300" rpy="0 3.14 3.14" />
  </xacro:us_sensor-->
  <!-- SENSOR 8 -->
  <!-- xacro:us_sensor name="us_8" parent="base_link">
    <origin xyz="0.170 0 0.300" rpy="0 3.14 3.14" />
  </xacro:us_sensor-->
  <!-- SENSOR 9 -->
  <!-- xacro:us_sensor name="us_9" parent="base_link">
    <origin xyz="0.180 0 0.300" rpy="0 3.14 3.14" />
  </xacro:us_sensor-->
  <!-- SENSOR 10 -->
  <!-- xacro:us_sensor name="us_10" parent="base_link">
    <origin xyz="0.100 0 0.300" rpy="0 3.14 3.14" />
  </xacro:us_sensor-->
  <!-- SENSOR 11 -->
  <!-- xacro:us_sensor name="us_11" parent="base_link">
    <origin xyz="0.100 0 0.300" rpy="0 3.14 3.14" />
  </xacro:us_sensor-->
  <!-- SENSOR 12 -->
  <!-- xacro:us_sensor name="us_12" parent="base_link">
    <origin xyz="0.190 0 0.300" rpy="0 3.14 3.14" />
  </xacro:us_sensor-->
  <!-- SENSOR 13 -->
  <!-- xacro:us_sensor name="us_13" parent="base_link">
    <origin xyz="0.200 0 0.300" rpy="0 3.14 3.14" />
  </xacro:us_sensor-->
  <!-- SENSOR 14 -->
  <!-- xacro:us_sensor name="us_14" parent="base_link">
    <origin xyz="0.210 0 0.300" rpy="0 3.14 3.14" />
  </xacro:us_sensor-->
  <!-- SENSOR 15 -->
  <!-- xacro:us_sensor name="us_15" parent="base_link">
    <origin xyz="0.220 0 0.300" rpy="0 3.14 3.14" />
  </xacro:us_sensor-->
  <!-- SENSOR 16 -->
  <!-- xacro:us_sensor name="us_16" parent="base_link">
    <origin xyz="0.230 0 0.300" rpy="0 3.14 3.14" />
  </xacro:us_sensor-->
  <joint name="cabinet_joint" type="fixed">
    <origin rpy="0 0 0" xyz="0.072 0 0.386"/>
    <joint_properties damping="1" friction="1"/>
    <parent link="base_link"/>
    <child link="cabinet_link"/>
  </joint>
  <link name="cabinet_link">
    <inertial>
      <mass value="2"/>
      <origin rpy="0 0 0" xyz="0 0 0"/>
      <inertia ixx="0.457072" ixy="0.0" ixz="0.0" iyy="0.23616" iyz="0.0" izz="0.686"/>
    </inertial>
    <visual>
      <origin rpy="0 0 -1.5708" xyz="0 0 0"/>
      <geometry>
        <mesh filename="package://neo_simulation/robots/mmo_500/meshes/cabin.dae" scale="0.001 0.001 0.001"/>
      </geometry>
    </visual>
    <collision>
      <origin rpy="0 0 0" xyz="0. 0. 0"/>
      <geometry>
        <mesh filename="package://neo_simulation/robots/mmo_500/meshes/cabin.dae" scale="0.001 0.001 0.001"/>
      </geometry>
    </collision>
  </link>
  <joint name="cabinet_u10_joint" type="fixed">
    <parent link="cabinet_link"/>
    <child link="ur10_base_link"/>
    <origin rpy="0.0 0.0 0.0" xyz="0.133 0.0 0.416"/>
  </joint>
  <link name="ur10_base_link">
    <visual>
      <geometry>
        <mesh filename="package://neo_simulation/robots/mmo_500/meshes/base.dae"/>
      </geometry>
    </visual>
    <collision>
      <geometry>
        <mesh filename="package://neo_simulation/robots/mmo_500/meshes/base.dae"/>
      </geometry>
    </collision>
    <inertial>
      <mass value="2.0"/>
      <origin rpy="0 0 0" xyz="0.0 0.0 0.0"/>
      <inertia ixx="0.0030531654454" ixy="0.0" ixz="0.0" iyy="0.0030531654454" iyz="0.0" izz="0.005625"/>
    </inertial>
  </link>
  <joint name="shoulder_pan_joint" type="revolute">
    <parent link="ur10_base_link"/>
    <child link="shoulder_link"/>
    <origin rpy="0.0 0.0 0.0" xyz="0.0 0.0 0.1273"/>
    <axis xyz="0 0 1"/>
    <limit effort="330.0" lower="-6.28318530718" upper="6.28318530718" velocity="2.16"/>
    <dynamics damping="0.5" friction="10.0"/>
  </joint>
  <link name="shoulder_link">
    <visual>
      <geometry>
        <mesh filename="package://neo_simulation/robots/mmo_500/meshes/shoulder.dae"/>
      </geometry>
    </visual>
    <collision>
      <geometry>
        <mesh filename="package://neo_simulation/robots/mmo_500/meshes/shoulder.dae"/>
      </geometry>
    </collision>
    <inertial>
      <mass value="7.778"/>
      <origin rpy="0 0 0" xyz="0.0 0.0 0.0"/>
      <inertia ixx="0.0314743125769" ixy="0.0" ixz="0.0" iyy="0.0314743125769" iyz="0.0" izz="0.021875625"/>
    </inertial>
  </link>
  <joint name="shoulder_lift_joint" type="revolute">
    <parent link="shoulder_link"/>
    <child link="upper_arm_link"/>
    <origin rpy="0.0 -1.25 0.0" xyz="0.0 0.220941 0.0"/>
    <axis xyz="0 1 0"/>
    <limit effort="330.0" lower="-3.14159265359" upper="3.14159265359" velocity="2.16"/>
    <dynamics damping="0.5" friction="10.0"/>
  </joint>
  <link name="upper_arm_link">
    <visual>
      <geometry>
        <mesh filename="package://neo_simulation/robots/mmo_500/meshes/upperarm.dae"/>
      </geometry>
    </visual>
    <collision>
      <geometry>
        <mesh filename="package://neo_simulation/robots/mmo_500/meshes/upperarm.dae"/>
      </geometry>
    </collision>
    <inertial>
      <mass value="12.93"/>
      <origin rpy="0 0 0" xyz="0.0 0.0 0.306"/>
      <inertia ixx="0.421753803798" ixy="0.0" ixz="0.0" iyy="0.421753803798" iyz="0.0" izz="0.036365625"/>
    </inertial>
  </link>
  <joint name="elbow_joint" type="revolute">
    <parent link="upper_arm_link"/>
    <child link="forearm_link"/>
    <origin rpy="0.0 -1.95 0.0" xyz="0.0 -0.1719 0.612"/>
    <axis xyz="0 1 0"/>
    <limit effort="150.0" lower="-3.14159265359" upper="3.14159265359" velocity="3.15"/>
    <dynamics damping="0.5" friction="10.0"/>
  </joint>
  <link name="forearm_link">
    <visual>
      <geometry>
        <mesh filename="package://neo_simulation/robots/mmo_500/meshes/forearm.dae"/>
      </geometry>
    </visual>
    <collision>
      <geometry>
        <mesh filename="package://neo_simulation/robots/mmo_500/meshes/forearm.dae"/>
      </geometry>
    </collision>
    <inertial>
      <mass value="3.87"/>
      <origin rpy="0 0 0" xyz="0.0 0.0 0.28615"/>
      <inertia ixx="0.111069694097" ixy="0.0" ixz="0.0" iyy="0.111069694097" iyz="0.0" izz="0.010884375"/>
    </inertial>
  </link>
  <joint name="wrist_1_joint" type="revolute">
    <parent link="forearm_link"/>
    <child link="wrist_1_link"/>
    <origin rpy="0.0 1.57079632679 0.0" xyz="0.0 0.0 0.5723"/>
    <axis xyz="0 1 0"/>
    <limit effort="54.0" lower="-3.14159265359" upper="3.14159265359" velocity="3.2"/>
    <dynamics damping="0.5" friction="10.0"/>
  </joint>
  <link name="wrist_1_link">
    <visual>
      <geometry>
        <mesh filename="package://neo_simulation/robots/mmo_500/meshes/wrist1.dae"/>
      </geometry>
    </visual>
    <collision>
      <geometry>
        <mesh filename="package://neo_simulation/robots/mmo_500/meshes/wrist1.dae"/>
      </geometry>
    </collision>
    <inertial>
      <mass value="1.96"/>
      <origin rpy="0 0 0" xyz="0.0 0.0 0.0"/>
      <inertia ixx="0.0051082479567" ixy="0.0" ixz="0.0" iyy="0.0051082479567" iyz="0.0" izz="0.0055125"/>
    </inertial>
  </link>
  <joint name="wrist_2_joint" type="revolute">
    <parent link="wrist_1_link"/>
    <child link="wrist_2_link"/>
    <origin rpy="0.0 0.0 0.0" xyz="0.0 0.1149 0.0"/>
    <axis xyz="0 0 1"/>
    <limit effort="54.0" lower="-3.14159265359" upper="3.14159265359" velocity="3.2"/>
    <dynamics damping="0.5" friction="10.0"/>
  </joint>
  <link name="wrist_2_link">
    <visual>
      <geometry>
        <mesh filename="package://neo_simulation/robots/mmo_500/meshes/wrist2.dae"/>
      </geometry>
    </visual>
    <collision>
      <geometry>
        <mesh filename="package://neo_simulation/robots/mmo_500/meshes/wrist2.dae"/>
      </geometry>
    </collision>
    <inertial>
      <mass value="1.96"/>
      <origin rpy="0 0 0" xyz="0.0 0.0 0.0"/>
      <inertia ixx="0.0051082479567" ixy="0.0" ixz="0.0" iyy="0.0051082479567" iyz="0.0" izz="0.0055125"/>
    </inertial>
  </link>
  <joint name="wrist_3_joint" type="revolute">
    <parent link="wrist_2_link"/>
    <child link="wrist_3_link"/>
    <origin rpy="0.0 0.0 0.0" xyz="0.0 0.0 0.1157"/>
    <axis xyz="0 1 0"/>
    <limit effort="54.0" lower="-3.14159265359" upper="3.14159265359" velocity="3.2"/>
    <dynamics damping="0.5" friction="10.0"/>
  </joint>
  <link name="wrist_3_link">
    <visual>
      <geometry>
        <mesh filename="package://neo_simulation/robots/mmo_500/meshes/wrist3.dae"/>
      </geometry>
    </visual>
    <collision>
      <geometry>
        <mesh filename="package://neo_simulation/robots/mmo_500/meshes/wrist3.dae"/>
      </geometry>
    </collision>
    <inertial>
      <mass value="0.202"/>
      <origin rpy="0 0 0" xyz="0.0 0.0 0.0"/>
      <inertia ixx="0.000526462289415" ixy="0.0" ixz="0.0" iyy="0.000526462289415" iyz="0.0" izz="0.000568125"/>
    </inertial>
  </link>
  <joint name="ee_fixed_joint" type="fixed">
    <parent link="wrist_3_link"/>
    <child link="ee_link"/>
    <origin rpy="0.0 0.0 1.57079632679" xyz="0.0 0.0922 0.0"/>
  </joint>
  <link name="ee_link">
    <collision>
      <geometry>
        <box size="0.01 0.01 0.01"/>
      </geometry>
      <origin rpy="0 0 0" xyz="-0.01 0 0"/>
    </collision>
  </link>
  <transmission name="shoulder_pan_trans">
    <type>transmission_interface/SimpleTransmission</type>
    <joint name="shoulder_pan_joint">
      <hardwareInterface>hardware_interface/PositionJointInterface</hardwareInterface>
    </joint>
    <actuator name="shoulder_pan_motor">
      <mechanicalReduction>1</mechanicalReduction>
    </actuator>
  </transmission>
  <transmission name="shoulder_lift_trans">
    <type>transmission_interface/SimpleTransmission</type>
    <joint name="shoulder_lift_joint">
      <hardwareInterface>hardware_interface/PositionJointInterface</hardwareInterface>
    </joint>
    <actuator name="shoulder_lift_motor">
      <mechanicalReduction>1</mechanicalReduction>
    </actuator>
  </transmission>
  <transmission name="elbow_trans">
    <type>transmission_interface/SimpleTransmission</type>
    <joint name="elbow_joint">
      <hardwareInterface>hardware_interface/PositionJointInterface</hardwareInterface>
    </joint>
    <actuator name="elbow_motor">
      <mechanicalReduction>1</mechanicalReduction>
    </actuator>
  </transmission>
  <transmission name="wrist_1_trans">
    <type>transmission_interface/SimpleTransmission</type>
    <joint name="wrist_1_joint">
      <hardwareInterface>hardware_interface/PositionJointInterface</hardwareInterface>
    </joint>
    <actuator name="wrist_1_motor">
      <mechanicalReduction>1</mechanicalReduction>
    </actuator>
  </transmission>
  <transmission name="wrist_2_trans">
    <type>transmission_interface/SimpleTransmission</type>
    <joint name="wrist_2_joint">
      <hardwareInterface>hardware_interface/PositionJointInterface</hardwareInterface>
    </joint>
    <actuator name="wrist_2_motor">
      <mechanicalReduction>1</mechanicalReduction>
    </actuator>
  </transmission>
  <transmission name="wrist_3_trans">
    <type>transmission_interface/SimpleTransmission</type>
    <joint name="wrist_3_joint">
      <hardwareInterface>hardware_interface/PositionJointInterface</hardwareInterface>
    </joint>
    <actuator name="wrist_3_motor">
      <mechanicalReduction>1</mechanicalReduction>
    </actuator>
  </transmission>
  <!-- nothing to do here at the moment -->
  <!-- ROS ur10_base_link to UR 'Base' Coordinates transform -->
  <link name="base"/>
  <joint name="ur10_base_link-base_fixed_joint" type="fixed">
    <!-- NOTE: this rotation is only needed as long as ur10_base_link itself is
                 not corrected wrt the real robot (ie: rotated over 180
                 degrees)
      -->
    <origin rpy="0 0 -3.14159265359" xyz="0 0 0"/>
    <parent link="ur10_base_link"/>
    <child link="base"/>
  </joint>
  <!-- Frame coincident with all-zeros TCP on UR controller -->
  <link name="tool0"/>
  <joint name="wrist_3_link-tool0_fixed_joint" type="fixed">
    <origin rpy="-1.57079632679 0 0" xyz="0 0.0922 0"/>
    <parent link="wrist_3_link"/>
    <child link="tool0"/>
  </joint>
  <link name="H1_base_attach"/>
  <material name="Blue">
    <color rgba="0.0 0.0 0.8 1.0"/>
  </material>
  <material name="Green">
    <color rgba="0.0 0.8 0.0 1.0"/>
  </material>
  <material name="BiotacGreen">
    <color rgba="0.31 0.85 0.42 1.0"/>
  </material>
  <material name="Grey">
    <color rgba="0.2 0.2 0.2 1.0"/>
  </material>
  <material name="LightGrey">
    <color rgba="0.6 0.6 0.6 1.0"/>
  </material>
  <material name="Red">
    <color rgba="0.8 0.0 0.0 1.0"/>
  </material>
  <material name="White">
    <color rgba="1.0 1.0 1.0 1.0"/>
  </material>
  <link name="H1_ur10_base_link">
    <inertial>
      <origin rpy="0 0 0" xyz="-8.6116E-06 -0.0058125 0.028294"/>
      <mass value="0.07527"/>
      <inertia ixx="0.00014442" ixy="1.2033E-08" ixz="-5.9646E-10" iyy="0.00014979" iyz="-1.0288E-05" izz="5.2943E-05"/>
    </inertial>
    <visual>
      <origin rpy="0 0 0" xyz="0 0 0"/>
      <geometry>
        <mesh filename="package://neo_simulation/robots/mmo_500/meshes/palm_link_simple.dae"/>
      </geometry>
      <material name="light_grey">
        <color rgba="0.75 0.75 0.75 1.0"/>
      </material>
    </visual>
    <collision>
      <origin rpy="0 0 0" xyz="0 0 0"/>
      <geometry>
        <mesh filename="package://neo_simulation/robots/mmo_500/meshes/palm_link_simple.dae"/>
      </geometry>
      <material name="light_grey">
        <color rgba="0.75 0.75 0.75 1.0"/>
      </material>
    </collision>
  </link>
  <joint name="H1Base" type="fixed">
    <origin rpy="0 0 0" xyz="0 0 0"/>
    <parent link="H1_base_attach"/>
    <child link="H1_wrist_attach"/>
  </joint>
  <link name="H1_insert_F1"/>
  <joint name="H1_dummy_joint_1" type="fixed">
    <origin rpy="0 0 2.3562" xyz="-0.045 -0.025981 0"/>
    <axis xyz="0 -1 0"/>
    <parent link="H1_ur10_base_link"/>
    <child link="H1_insert_F1"/>
  </joint>
  <link name="H1_insert_F2"/>
  <joint name="H1_dummy_joint_2" type="fixed">
    <origin rpy="0 0 0" xyz="0 0.029019 0"/>
    <axis xyz="0 -1 0"/>
    <parent link="H1_ur10_base_link"/>
    <child link="H1_insert_F2"/>
  </joint>
  <link name="H1_insert_F3"/>
  <joint name="H1_dummy_joint_3" type="fixed">
    <origin rpy="0 0 -2.3562" xyz="0.045 -0.025981 0"/>
    <axis xyz="0 -1 0"/>
    <parent link="H1_ur10_base_link"/>
    <child link="H1_insert_F3"/>
  </joint>
  <link name="H1_wrist_attach"/>
  <joint name="H1_ur10_base_link_wrist_attach" type="fixed">
    <origin rpy="0 0 0" xyz="0 0 -0.0005"/>
    <child link="H1_ur10_base_link"/>
    <parent link="H1_wrist_attach"/>
  </joint>
  <link name="H1_F1_palm_link">
    <inertial>
      <origin rpy="0 0 0" xyz="-0.00681802120880393 -0.00947020456878004 0.067587996682422"/>
      <mass value="0.0341482312344481"/>
      <inertia ixx="2.79747833772125E-05" ixy="-5.50900644725373E-08" ixz="-2.82072424927723E-07" iyy="2.67800858812928E-05" iyz="3.1953125069394E-06" izz="9.86122271726361E-06"/>
    </inertial>
    <visual>
      <origin rpy="0 0 0" xyz="0 0 0"/>
      <geometry>
        <mesh filename="package://neo_simulation/robots/mmo_500/meshes/finger_palm_link.dae"/>
      </geometry>
      <material name="light_grey">
        <color rgba="0.75 0.75 0.75 1.0"/>
      </material>
    </visual>
    <!-- Collision mesh no needed as it is part of palm_link_simple.dae collision mesh -->
    <!--xacro:mesh_collision file_name="finger_palm_link.dae">
        <origin xyz="0 0 0" rpy="0 0 0" />
        <xacro:light_grey/>
      </xacro:mesh_collision-->
  </link>
  <link name="H1_F1_ur10_base_link">
    <inertial>
      <origin rpy="0 0 0" xyz="-0.000142856770000038 0.0265691681336443 0.0538751581621436"/>
      <mass value="0.174652229503358"/>
      <inertia ixx="0.000298372741514267" ixy="-5.05751882577435E-07" ixz="1.94982779411417E-07" iyy="0.000299629589232877" iyz="2.79565205733806E-05" izz="0.000134889645145365"/>
    </inertial>
    <visual>
      <origin rpy="0 0 0" xyz="0 0 0"/>
      <geometry>
        <mesh filename="package://neo_simulation/robots/mmo_500/meshes/finger_base_link_simple.dae"/>
      </geometry>
      <material name="light_grey">
        <color rgba="0.75 0.75 0.75 1.0"/>
      </material>
    </visual>
    <collision>
      <origin rpy="0 0 0" xyz="0 0 0"/>
      <geometry>
        <mesh filename="package://neo_simulation/robots/mmo_500/meshes/finger_base_link_simple.dae"/>
      </geometry>
      <material name="light_grey">
        <color rgba="0.75 0.75 0.75 1.0"/>
      </material>
    </collision>
  </link>
  <link name="H1_F1_link_1">
    <inertial>
      <origin rpy="0 0 0" xyz="-0.000141876508729455 -0.00135409566494088 0.0277606215980989"/>
      <mass value="0.0827759744227546"/>
      <inertia ixx="4.61070151157777E-05" ixy="7.47741111557837E-08" ixz="-2.25165057702697E-07" iyy="5.27678327317508E-05" iyz="-3.64603343546298E-07" izz="2.89599551320955E-05"/>
    </inertial>
    <visual>
      <origin rpy="0 0 0" xyz="0 0 0"/>
      <geometry>
        <mesh filename="package://neo_simulation/robots/mmo_500/meshes/finger_prox_link_simple.dae"/>
      </geometry>
      <material name="light_grey">
        <color rgba="0.75 0.75 0.75 1.0"/>
      </material>
    </visual>
    <collision>
      <origin rpy="0 0 0" xyz="0 0 0"/>
      <geometry>
        <mesh filename="package://neo_simulation/robots/mmo_500/meshes/finger_prox_link_simple.dae"/>
      </geometry>
      <material name="light_grey">
        <color rgba="0.75 0.75 0.75 1.0"/>
      </material>
    </collision>
  </link>
  <link name="H1_F1_link_2">
    <inertial>
      <origin rpy="0 0 0" xyz="0.000506812071918918 -0.00091292934992606 0.0156620851768385"/>
      <mass value="0.0270049614151599"/>
      <inertia ixx="1.06942730265546E-05" ixy="-7.1810089794211E-09" ixz="-3.49957211410822E-07" iyy="1.05772889540593E-05" iyz="-8.38595987731518E-07" izz="3.27173446995846E-06"/>
    </inertial>
    <visual>
      <origin rpy="0 0 0" xyz="0 0 0"/>
      <geometry>
        <mesh filename="package://neo_simulation/robots/mmo_500/meshes/finger_dist_link_simple.dae"/>
      </geometry>
      <material name="light_grey">
        <color rgba="0.75 0.75 0.75 1.0"/>
      </material>
    </visual>
    <collision>
      <origin rpy="0 0 0" xyz="0 0 0"/>
      <geometry>
        <mesh filename="package://neo_simulation/robots/mmo_500/meshes/finger_dist_link_simple.dae"/>
      </geometry>
      <material name="light_grey">
        <color rgba="0.75 0.75 0.75 1.0"/>
      </material>
    </collision>
  </link>
  <joint name="H1_F1Palm" type="fixed">
    <origin rpy="0 0 0" xyz="0 0 0"/>
    <parent link="H1_insert_F1"/>
    <child link="H1_F1_palm_link"/>
  </joint>
  <joint name="H1_F1J1" type="fixed">
    <origin rpy="-8.8818E-16 -1.0061E-16 0.022402" xyz="0 0 0.00016528"/>
    <axis xyz="0 0 1"/>
    <parent link="H1_F1_palm_link"/>
    <child link="H1_F1_ur10_base_link"/>
    <limit effort="50" lower="-0.785398163397" upper="0.785398163397" velocity="1.0"/>
    <dynamics damping="0.0" friction="10.0"/>
  </joint>
  <joint name="H1_F1J2" type="fixed">
    <origin rpy="0.070695 6.9389E-16 2.0947E-16" xyz="0 0.035 0.11683"/>
    <axis xyz="1 0 0"/>
    <parent link="H1_F1_ur10_base_link"/>
    <child link="H1_F1_link_1"/>
    <limit effort="50" lower="-1.3962634016" upper="1.0471975512" velocity="1.0"/>
    <dynamics damping="0.0" friction="10.0"/>
  </joint>
  <joint name="H1_F1J3" type="revolute">
    <origin rpy="-0.0068649 1.7347E-18 1.6176E-16" xyz="0 0 0.06"/>
    <axis xyz="1 0 0"/>
    <parent link="H1_F1_link_1"/>
    <child link="H1_F1_link_2"/>
    <limit effort="50" lower="-1.0471975512" upper="1.57079632679" velocity="1.0"/>
    <dynamics damping="0.0" friction="10.0"/>
  </joint>
  <transmission name="H1_F1J3_transmission">
    <type>transmission_interface/SimpleTransmission</type>
    <actuator name="H1_F1J3">
      <mechanicalReduction>1</mechanicalReduction>
    </actuator>
    <joint name="H1_F1J3">
      <hardwareInterface>hardware_interface/PositionJointInterface</hardwareInterface>
    </joint>
  </transmission>
  <!-- finger tip -->
  <link name="H1_F1_tip">
    <inertial>
      <origin rpy="0 0 0" xyz="-0.000925580990320645 -0.00495543398528436 0.0355865585792753"/>
      <mass value="0.00906322686585137"/>
      <inertia ixx="1.10049088227995E-06" ixy="-3.7290982171096E-09" ixz="-9.54389365908683E-09" iyy="1.36130530510584E-06" iyz="6.66133713720777E-08" izz="6.42259773618367E-07"/>
    </inertial>
    <visual>
      <origin rpy="0 0 0" xyz="0 0 0"/>
      <geometry>
        <mesh filename="package://neo_simulation/robots/mmo_500/meshes/omd-d18-tip.dae"/>
      </geometry>
      <material name="light_grey">
        <color rgba="0.75 0.75 0.75 1.0"/>
      </material>
    </visual>
    <collision>
      <origin rpy="0 0 0" xyz="0 0 0"/>
      <geometry>
        <mesh filename="package://neo_simulation/robots/mmo_500/meshes/omd-d18-tip.dae"/>
      </geometry>
      <material name="light_grey">
        <color rgba="0.75 0.75 0.75 1.0"/>
      </material>
    </collision>
  </link>
  <link name="H1_F1_optoforce"/>
  <joint name="H1_F1_tip_to_optoforce" type="fixed">
    <parent link="H1_F1_tip"/>
    <child link="H1_F1_optoforce"/>
    <origin rpy="-0.35 0 0" xyz="0 -0.006 0.046"/>
  </joint>
  <joint name="H1_F1_tip" type="fixed">
    <parent link="H1_F1_link_2"/>
    <child link="H1_F1_tip"/>
  </joint>
  <link name="H1_F2_palm_link">
    <inertial>
      <origin rpy="0 0 0" xyz="-0.00681802120880393 -0.00947020456878004 0.067587996682422"/>
      <mass value="0.0341482312344481"/>
      <inertia ixx="2.79747833772125E-05" ixy="-5.50900644725373E-08" ixz="-2.82072424927723E-07" iyy="2.67800858812928E-05" iyz="3.1953125069394E-06" izz="9.86122271726361E-06"/>
    </inertial>
    <visual>
      <origin rpy="0 0 0" xyz="0 0 0"/>
      <geometry>
        <mesh filename="package://neo_simulation/robots/mmo_500/meshes/finger_palm_link.dae"/>
      </geometry>
      <material name="light_grey">
        <color rgba="0.75 0.75 0.75 1.0"/>
      </material>
    </visual>
    <!-- Collision mesh no needed as it is part of palm_link_simple.dae collision mesh -->
    <!--xacro:mesh_collision file_name="finger_palm_link.dae">
        <origin xyz="0 0 0" rpy="0 0 0" />
        <xacro:light_grey/>
      </xacro:mesh_collision-->
  </link>
  <link name="H1_F2_ur10_base_link">
    <inertial>
      <origin rpy="0 0 0" xyz="-0.000142856770000038 0.0265691681336443 0.0538751581621436"/>
      <mass value="0.174652229503358"/>
      <inertia ixx="0.000298372741514267" ixy="-5.05751882577435E-07" ixz="1.94982779411417E-07" iyy="0.000299629589232877" iyz="2.79565205733806E-05" izz="0.000134889645145365"/>
    </inertial>
    <visual>
      <origin rpy="0 0 0" xyz="0 0 0"/>
      <geometry>
        <mesh filename="package://neo_simulation/robots/mmo_500/meshes/finger_base_link_simple.dae"/>
      </geometry>
      <material name="light_grey">
        <color rgba="0.75 0.75 0.75 1.0"/>
      </material>
    </visual>
    <collision>
      <origin rpy="0 0 0" xyz="0 0 0"/>
      <geometry>
        <mesh filename="package://neo_simulation/robots/mmo_500/meshes/finger_base_link_simple.dae"/>
      </geometry>
      <material name="light_grey">
        <color rgba="0.75 0.75 0.75 1.0"/>
      </material>
    </collision>
  </link>
  <link name="H1_F2_link_1">
    <inertial>
      <origin rpy="0 0 0" xyz="-0.000141876508729455 -0.00135409566494088 0.0277606215980989"/>
      <mass value="0.0827759744227546"/>
      <inertia ixx="4.61070151157777E-05" ixy="7.47741111557837E-08" ixz="-2.25165057702697E-07" iyy="5.27678327317508E-05" iyz="-3.64603343546298E-07" izz="2.89599551320955E-05"/>
    </inertial>
    <visual>
      <origin rpy="0 0 0" xyz="0 0 0"/>
      <geometry>
        <mesh filename="package://neo_simulation/robots/mmo_500/meshes/finger_prox_link_simple.dae"/>
      </geometry>
      <material name="light_grey">
        <color rgba="0.75 0.75 0.75 1.0"/>
      </material>
    </visual>
    <collision>
      <origin rpy="0 0 0" xyz="0 0 0"/>
      <geometry>
        <mesh filename="package://neo_simulation/robots/mmo_500/meshes/finger_prox_link_simple.dae"/>
      </geometry>
      <material name="light_grey">
        <color rgba="0.75 0.75 0.75 1.0"/>
      </material>
    </collision>
  </link>
  <link name="H1_F2_link_2">
    <inertial>
      <origin rpy="0 0 0" xyz="0.000506812071918918 -0.00091292934992606 0.0156620851768385"/>
      <mass value="0.0270049614151599"/>
      <inertia ixx="1.06942730265546E-05" ixy="-7.1810089794211E-09" ixz="-3.49957211410822E-07" iyy="1.05772889540593E-05" iyz="-8.38595987731518E-07" izz="3.27173446995846E-06"/>
    </inertial>
    <visual>
      <origin rpy="0 0 0" xyz="0 0 0"/>
      <geometry>
        <mesh filename="package://neo_simulation/robots/mmo_500/meshes/finger_dist_link_simple.dae"/>
      </geometry>
      <material name="light_grey">
        <color rgba="0.75 0.75 0.75 1.0"/>
      </material>
    </visual>
    <collision>
      <origin rpy="0 0 0" xyz="0 0 0"/>
      <geometry>
        <mesh filename="package://neo_simulation/robots/mmo_500/meshes/finger_dist_link_simple.dae"/>
      </geometry>
      <material name="light_grey">
        <color rgba="0.75 0.75 0.75 1.0"/>
      </material>
    </collision>
  </link>
  <joint name="H1_F2Palm" type="fixed">
    <origin rpy="0 0 0" xyz="0 0 0"/>
    <parent link="H1_insert_F2"/>
    <child link="H1_F2_palm_link"/>
  </joint>
  <joint name="H1_F2J1" type="fixed">
    <origin rpy="-8.8818E-16 -1.0061E-16 0.022402" xyz="0 0 0.00016528"/>
    <axis xyz="0 0 1"/>
    <parent link="H1_F2_palm_link"/>
    <child link="H1_F2_ur10_base_link"/>
    <limit effort="30" lower="-0.785398163397" upper="0.785398163397" velocity="1.0"/>
    <dynamics damping="0.0" friction="10.0"/>
  </joint>
  <joint name="H1_F2J2" type="fixed">
    <origin rpy="0.070695 6.9389E-16 2.0947E-16" xyz="0 0.035 0.11683"/>
    <axis xyz="1 0 0"/>
    <parent link="H1_F2_ur10_base_link"/>
    <child link="H1_F2_link_1"/>
    <limit effort="30" lower="-1.3962634016" upper="1.0471975512" velocity="1.0"/>
    <dynamics damping="0.0" friction="10.0"/>
  </joint>
  <joint name="H1_F2J3" type="revolute">
    <origin rpy="-0.0068649 1.7347E-18 1.6176E-16" xyz="0 0 0.06"/>
    <axis xyz="1 0 0"/>
    <parent link="H1_F2_link_1"/>
    <child link="H1_F2_link_2"/>
    <limit effort="30" lower="-1.0471975512" upper="1.57079632679" velocity="1.0"/>
    <dynamics damping="0.0" friction="10.0"/>
  </joint>
  <transmission name="H1_F2J3_transmission">
    <type>transmission_interface/SimpleTransmission</type>
    <actuator name="H1_F2J3">
      <mechanicalReduction>1</mechanicalReduction>
    </actuator>
    <joint name="H1_F2J3">
      <hardwareInterface>hardware_interface/PositionJointInterface</hardwareInterface>
    </joint>
  </transmission>
  <!-- finger tip -->
  <link name="H1_F2_tip">
    <inertial>
      <origin rpy="0 0 0" xyz="-0.000925580990320645 -0.00495543398528436 0.0355865585792753"/>
      <mass value="0.00906322686585137"/>
      <inertia ixx="1.10049088227995E-06" ixy="-3.7290982171096E-09" ixz="-9.54389365908683E-09" iyy="1.36130530510584E-06" iyz="6.66133713720777E-08" izz="6.42259773618367E-07"/>
    </inertial>
    <visual>
      <origin rpy="0 0 0" xyz="0 0 0"/>
      <geometry>
        <mesh filename="package://neo_simulation/robots/mmo_500/meshes/omd-d18-tip.dae"/>
      </geometry>
      <material name="light_grey">
        <color rgba="0.75 0.75 0.75 1.0"/>
      </material>
    </visual>
    <collision>
      <origin rpy="0 0 0" xyz="0 0 0"/>
      <geometry>
        <mesh filename="package://neo_simulation/robots/mmo_500/meshes/omd-d18-tip.dae"/>
      </geometry>
      <material name="light_grey">
        <color rgba="0.75 0.75 0.75 1.0"/>
      </material>
    </collision>
  </link>
  <link name="H1_F2_optoforce"/>
  <joint name="H1_F2_tip_to_optoforce" type="fixed">
    <parent link="H1_F2_tip"/>
    <child link="H1_F2_optoforce"/>
    <origin rpy="-0.35 0 0" xyz="0 -0.006 0.046"/>
  </joint>
  <joint name="H1_F2_tip" type="fixed">
    <parent link="H1_F2_link_2"/>
    <child link="H1_F2_tip"/>
  </joint>
  <link name="H1_F3_palm_link">
    <inertial>
      <origin rpy="0 0 0" xyz="-0.00681802120880393 -0.00947020456878004 0.067587996682422"/>
      <mass value="0.0341482312344481"/>
      <inertia ixx="2.79747833772125E-05" ixy="-5.50900644725373E-08" ixz="-2.82072424927723E-07" iyy="2.67800858812928E-05" iyz="3.1953125069394E-06" izz="9.86122271726361E-06"/>
    </inertial>
    <visual>
      <origin rpy="0 0 0" xyz="0 0 0"/>
      <geometry>
        <mesh filename="package://neo_simulation/robots/mmo_500/meshes/finger_palm_link.dae"/>
      </geometry>
      <material name="light_grey">
        <color rgba="0.75 0.75 0.75 1.0"/>
      </material>
    </visual>
    <!-- Collision mesh no needed as it is part of palm_link_simple.dae collision mesh -->
    <!--xacro:mesh_collision file_name="finger_palm_link.dae">
        <origin xyz="0 0 0" rpy="0 0 0" />
        <xacro:light_grey/>
      </xacro:mesh_collision-->
  </link>
  <link name="H1_F3_ur10_base_link">
    <inertial>
      <origin rpy="0 0 0" xyz="-0.000142856770000038 0.0265691681336443 0.0538751581621436"/>
      <mass value="0.174652229503358"/>
      <inertia ixx="0.000298372741514267" ixy="-5.05751882577435E-07" ixz="1.94982779411417E-07" iyy="0.000299629589232877" iyz="2.79565205733806E-05" izz="0.000134889645145365"/>
    </inertial>
    <visual>
      <origin rpy="0 0 0" xyz="0 0 0"/>
      <geometry>
        <mesh filename="package://neo_simulation/robots/mmo_500/meshes/finger_base_link_simple.dae"/>
      </geometry>
      <material name="light_grey">
        <color rgba="0.75 0.75 0.75 1.0"/>
      </material>
    </visual>
    <collision>
      <origin rpy="0 0 0" xyz="0 0 0"/>
      <geometry>
        <mesh filename="package://neo_simulation/robots/mmo_500/meshes/finger_base_link_simple.dae"/>
      </geometry>
      <material name="light_grey">
        <color rgba="0.75 0.75 0.75 1.0"/>
      </material>
    </collision>
  </link>
  <link name="H1_F3_link_1">
    <inertial>
      <origin rpy="0 0 0" xyz="-0.000141876508729455 -0.00135409566494088 0.0277606215980989"/>
      <mass value="0.0827759744227546"/>
      <inertia ixx="4.61070151157777E-05" ixy="7.47741111557837E-08" ixz="-2.25165057702697E-07" iyy="5.27678327317508E-05" iyz="-3.64603343546298E-07" izz="2.89599551320955E-05"/>
    </inertial>
    <visual>
      <origin rpy="0 0 0" xyz="0 0 0"/>
      <geometry>
        <mesh filename="package://neo_simulation/robots/mmo_500/meshes/finger_prox_link_simple.dae"/>
      </geometry>
      <material name="light_grey">
        <color rgba="0.75 0.75 0.75 1.0"/>
      </material>
    </visual>
    <collision>
      <origin rpy="0 0 0" xyz="0 0 0"/>
      <geometry>
        <mesh filename="package://neo_simulation/robots/mmo_500/meshes/finger_prox_link_simple.dae"/>
      </geometry>
      <material name="light_grey">
        <color rgba="0.75 0.75 0.75 1.0"/>
      </material>
    </collision>
  </link>
  <link name="H1_F3_link_2">
    <inertial>
      <origin rpy="0 0 0" xyz="0.000506812071918918 -0.00091292934992606 0.0156620851768385"/>
      <mass value="0.0270049614151599"/>
      <inertia ixx="1.06942730265546E-05" ixy="-7.1810089794211E-09" ixz="-3.49957211410822E-07" iyy="1.05772889540593E-05" iyz="-8.38595987731518E-07" izz="3.27173446995846E-06"/>
    </inertial>
    <visual>
      <origin rpy="0 0 0" xyz="0 0 0"/>
      <geometry>
        <mesh filename="package://neo_simulation/robots/mmo_500/meshes/finger_dist_link_simple.dae"/>
      </geometry>
      <material name="light_grey">
        <color rgba="0.75 0.75 0.75 1.0"/>
      </material>
    </visual>
    <collision>
      <origin rpy="0 0 0" xyz="0 0 0"/>
      <geometry>
        <mesh filename="package://neo_simulation/robots/mmo_500/meshes/finger_dist_link_simple.dae"/>
      </geometry>
      <material name="light_grey">
        <color rgba="0.75 0.75 0.75 1.0"/>
      </material>
    </collision>
  </link>
  <joint name="H1_F3Palm" type="fixed">
    <origin rpy="0 0 0" xyz="0 0 0"/>
    <parent link="H1_insert_F3"/>
    <child link="H1_F3_palm_link"/>
  </joint>
  <joint name="H1_F3J1" type="fixed">
    <origin rpy="-8.8818E-16 -1.0061E-16 0.022402" xyz="0 0 0.00016528"/>
    <axis xyz="0 0 1"/>
    <parent link="H1_F3_palm_link"/>
    <child link="H1_F3_ur10_base_link"/>
    <limit effort="30" lower="-0.785398163397" upper="0.785398163397" velocity="1.0"/>
    <dynamics damping="0.0" friction="10.0"/>
  </joint>
  <joint name="H1_F3J2" type="fixed">
    <origin rpy="0.070695 6.9389E-16 2.0947E-16" xyz="0 0.035 0.11683"/>
    <axis xyz="1 0 0"/>
    <parent link="H1_F3_ur10_base_link"/>
    <child link="H1_F3_link_1"/>
    <limit effort="30" lower="-1.3962634016" upper="1.0471975512" velocity="1.0"/>
    <dynamics damping="0.0" friction="10.0"/>
  </joint>
  <joint name="H1_F3J3" type="revolute">
    <origin rpy="-0.0068649 1.7347E-18 1.6176E-16" xyz="0 0 0.06"/>
    <axis xyz="1 0 0"/>
    <parent link="H1_F3_link_1"/>
    <child link="H1_F3_link_2"/>
    <limit effort="30" lower="-1.0471975512" upper="1.57079632679" velocity="1.0"/>
    <dynamics damping="0.0" friction="10.0"/>
  </joint>
  <transmission name="H1_F3J3_transmission">
    <type>transmission_interface/SimpleTransmission</type>
    <actuator name="H1_F3J3">
      <mechanicalReduction>1</mechanicalReduction>
    </actuator>
    <joint name="H1_F3J3">
      <hardwareInterface>hardware_interface/PositionJointInterface</hardwareInterface>
    </joint>
  </transmission>
  <!-- finger tip -->
  <link name="H1_F3_tip">
    <inertial>
      <origin rpy="0 0 0" xyz="-0.000925580990320645 -0.00495543398528436 0.0355865585792753"/>
      <mass value="0.00906322686585137"/>
      <inertia ixx="1.10049088227995E-06" ixy="-3.7290982171096E-09" ixz="-9.54389365908683E-09" iyy="1.36130530510584E-06" iyz="6.66133713720777E-08" izz="6.42259773618367E-07"/>
    </inertial>
    <visual>
      <origin rpy="0 0 0" xyz="0 0 0"/>
      <geometry>
        <mesh filename="package://neo_simulation/robots/mmo_500/meshes/omd-d18-tip.dae"/>
      </geometry>
      <material name="light_grey">
        <color rgba="0.75 0.75 0.75 1.0"/>
      </material>
    </visual>
    <collision>
      <origin rpy="0 0 0" xyz="0 0 0"/>
      <geometry>
        <mesh filename="package://neo_simulation/robots/mmo_500/meshes/omd-d18-tip.dae"/>
      </geometry>
      <material name="light_grey">
        <color rgba="0.75 0.75 0.75 1.0"/>
      </material>
    </collision>
  </link>
  <link name="H1_F3_optoforce"/>
  <joint name="H1_F3_tip_to_optoforce" type="fixed">
    <parent link="H1_F3_tip"/>
    <child link="H1_F3_optoforce"/>
    <origin rpy="-0.35 0 0" xyz="0 -0.006 0.046"/>
  </joint>
  <joint name="H1_F3_tip" type="fixed">
    <parent link="H1_F3_link_2"/>
    <child link="H1_F3_tip"/>
  </joint>
  <joint name="arm_to_hand" type="fixed">
    <parent link="ee_link"/>
    <child link="H1_base_attach"/>
    <origin rpy="1.57079632679 3.14159265359 1.57079632679" xyz="0.012 0.0 0.0"/>
  </joint>
  <gazebo reference="H1_F1J1">
    <implicitSpringDamper>1</implicitSpringDamper>
  </gazebo>
  <gazebo reference="H1_F1J2">
    <implicitSpringDamper>1</implicitSpringDamper>
  </gazebo>
  <gazebo reference="H1_F1J3">
    <implicitSpringDamper>1</implicitSpringDamper>
  </gazebo>
  <gazebo reference="H1_F2J1">
    <implicitSpringDamper>1</implicitSpringDamper>
  </gazebo>
  <gazebo reference="H1_F2J2">
    <implicitSpringDamper>1</implicitSpringDamper>
  </gazebo>
  <gazebo reference="H1_F2J3">
    <implicitSpringDamper>1</implicitSpringDamper>
  </gazebo>
  <gazebo reference="H1_F3J1">
    <implicitSpringDamper>1</implicitSpringDamper>
  </gazebo>
  <gazebo reference="H1_F3J2">
    <implicitSpringDamper>1</implicitSpringDamper>
  </gazebo>
  <gazebo reference="H1_F3J3">
    <implicitSpringDamper>1</implicitSpringDamper>
  </gazebo>
  <gazebo reference="H1_F1_link_1">
    <kp>1000000.0</kp>
    <kd>100.0</kd>
    <mu1>100000</mu1>
    <mu2>100000</mu2>
    <fdir1>1 0 0</fdir1>
    <maxVel>1.0</maxVel>
    <minDepth>0.001</minDepth>
    <material>Gazebo/DarkGrey</material>
  </gazebo>
  <gazebo reference="H1_F1_link_2">
    <kp>1000000.0</kp>
    <kd>100.0</kd>
    <mu1>100000</mu1>
    <mu2>100000</mu2>
    <fdir1>1 0 0</fdir1>
    <maxVel>1.0</maxVel>
    <minDepth>0.001</minDepth>
    <material>Gazebo/DarkGrey</material>
  </gazebo>
  <gazebo reference="H1_F1_tip">
    <kp>1000000.0</kp>
    <kd>10.0</kd>
    <mu1>100000</mu1>
    <mu2>100000</mu2>
    <fdir1>1 0 0</fdir1>
    <maxVel>1.0</maxVel>
    <minDepth>0.001</minDepth>
    <material>Gazebo/DarkGrey</material>
  </gazebo>
  <gazebo reference="H1_F2_link_1">
    <kp>1000000.0</kp>
    <kd>10.0</kd>
    <mu1>100000</mu1>
    <mu2>100000</mu2>
    <fdir1>1 0 0</fdir1>
    <maxVel>1.0</maxVel>
    <minDepth>0.001</minDepth>
    <material>Gazebo/DarkGrey</material>
  </gazebo>
  <gazebo reference="H1_F2_link_2">
    <kp>1000000.0</kp>
    <kd>10.0</kd>
    <mu1>100000</mu1>
    <mu2>100000</mu2>
    <fdir1>1 0 0</fdir1>
    <maxVel>1.0</maxVel>
    <minDepth>0.001</minDepth>
    <material>Gazebo/DarkGrey</material>
  </gazebo>
  <gazebo reference="H1_F2_tip">
    <kp>1000000.0</kp>
    <kd>10.0</kd>
    <mu1>100000</mu1>
    <mu2>100000</mu2>
    <fdir1>1 0 0</fdir1>
    <maxVel>1.0</maxVel>
    <minDepth>0.001</minDepth>
    <material>Gazebo/DarkGrey</material>
  </gazebo>
  <gazebo reference="H1_F3_link_1">
    <kp>1000000.0</kp>
    <kd>10.0</kd>
    <mu1>100000</mu1>
    <mu2>100000</mu2>
    <fdir1>1 0 0</fdir1>
    <maxVel>1.0</maxVel>
    <minDepth>0.001</minDepth>
    <material>Gazebo/DarkGrey</material>
  </gazebo>
  <gazebo reference="H1_F3_link_2">
    <kp>1000000.0</kp>
    <kd>10.0</kd>
    <mu1>100000</mu1>
    <mu2>100000</mu2>
    <fdir1>1 0 0</fdir1>
    <maxVel>1.0</maxVel>
    <minDepth>0.001</minDepth>
    <material>Gazebo/DarkGrey</material>
  </gazebo>
  <gazebo reference="H1_F3_tip">
    <kp>1000000.0</kp>
    <kd>10.0</kd>
    <mu1>100000</mu1>
    <mu2>100000</mu2>
    <fdir1>1 0 0</fdir1>
    <maxVel>1.0</maxVel>
    <minDepth>0.001</minDepth>
    <material>Gazebo/DarkGrey</material>
  </gazebo>
  <gazebo reference="H1_F1_ur10_base_link">
    <kp>1000000.0</kp>
    <kd>10.0</kd>
    <mu1>1000</mu1>
    <mu2>1000</mu2>
    <fdir1>1 0 0</fdir1>
    <maxVel>1.0</maxVel>
    <minDepth>0.001</minDepth>
    <material>Gazebo/DarkGrey</material>
  </gazebo>
  <gazebo reference="H1_F2_ur10_base_link">
    <kp>1000000.0</kp>
    <kd>10.0</kd>
    <mu1>100000</mu1>
    <mu2>100000</mu2>
    <fdir1>1 0 0</fdir1>
    <maxVel>1.0</maxVel>
    <minDepth>0.001</minDepth>
    <material>Gazebo/DarkGrey</material>
  </gazebo>
  <gazebo reference="H1_F3_ur10_base_link">
    <kp>1000000.0</kp>
    <kd>10.0</kd>
    <mu1>100000</mu1>
    <mu2>100000</mu2>
    <fdir1>1 0 0</fdir1>
    <maxVel>1.0</maxVel>
    <minDepth>0.001</minDepth>
    <material>Gazebo/DarkGrey</material>
  </gazebo>
  <gazebo reference="H1_F1_palm_link">
    <kp>1000000.0</kp>
    <kd>10.0</kd>
    <mu1>100000</mu1>
    <mu2>100000</mu2>
    <fdir1>1 0 0</fdir1>
    <maxVel>1.0</maxVel>
    <minDepth>0.001</minDepth>
    <material>Gazebo/DarkGrey</material>
  </gazebo>
  <gazebo reference="H1_F2_palm_link">
    <kp>1000000.0</kp>
    <kd>10.0</kd>
    <mu1>100000</mu1>
    <mu2>100000</mu2>
    <fdir1>1 0 0</fdir1>
    <maxVel>1.0</maxVel>
    <minDepth>0.001</minDepth>
    <material>Gazebo/DarkGrey</material>
  </gazebo>
  <gazebo reference="H1_F3_palm_link">
    <kp>1000000.0</kp>
    <kd>10.0</kd>
    <mu1>100000</mu1>
    <mu2>100000</mu2>
    <fdir1>1 0 0</fdir1>
    <maxVel>1.0</maxVel>
    <minDepth>0.001</minDepth>
    <material>Gazebo/DarkGrey</material>
  </gazebo>
  <gazebo reference="H1_ur10_base_link">
    <kp>1000000.0</kp>
    <kd>10.0</kd>
    <mu1>100000</mu1>
    <mu2>100000</mu2>
    <fdir1>1 0 0</fdir1>
    <maxVel>1.0</maxVel>
    <minDepth>0.001</minDepth>
    <material>Gazebo/DarkGrey</material>
  </gazebo>
  <!-- Pilz arm -->
  <!--     <xacro:prbt parent="cabinet_link" prefix="pilz">
    <origin xyz="0 0 0." rpy="0 0 0" />
  </xacro:prbt>
 -->
  <transmission name="mpo_500_omni_wheel_front_left">
    <type>transmission_interface/SimpleTransmission</type>
    <joint name="mpo_500_omni_wheel_front_left_joint">
      <hardwareInterface>hardware_interface/VelocityJointInterface</hardwareInterface>
    </joint>
    <actuator name="mpo_500_omni_wheel_front_left_motor">
      <mechanicalReduction>1</mechanicalReduction>
    </actuator>
  </transmission>
  <transmission name="mpo_500_omni_wheel_front_right">
    <type>transmission_interface/SimpleTransmission</type>
    <joint name="mpo_500_omni_wheel_front_right_joint">
      <hardwareInterface>hardware_interface/VelocityJointInterface</hardwareInterface>
    </joint>
    <actuator name="mpo_500_omni_wheel_front_right_motor">
      <mechanicalReduction>1</mechanicalReduction>
    </actuator>
  </transmission>
  <transmission name="mpo_500_omni_wheel_back_left">
    <type>transmission_interface/SimpleTransmission</type>
    <joint name="mpo_500_omni_wheel_back_left_joint">
      <hardwareInterface>hardware_interface/VelocityJointInterface</hardwareInterface>
    </joint>
    <actuator name="mpo_500_omni_wheel_back_left_motor">
      <mechanicalReduction>1</mechanicalReduction>
    </actuator>
  </transmission>
  <transmission name="mpo_500_omni_wheel_back_right">
    <type>transmission_interface/SimpleTransmission</type>
    <joint name="mpo_500_omni_wheel_back_right_joint">
      <hardwareInterface>hardware_interface/VelocityJointInterface</hardwareInterface>
    </joint>
    <actuator name="mpo_500_omni_wheel_back_right_motor">
      <mechanicalReduction>1</mechanicalReduction>
    </actuator>
  </transmission>
</robot>

