<?xml version="1.0" ?>

<robot name="mmo_500_ppr" xmlns:xacro="http://www.ros.org/wiki/xacro">

  <link name="world">
      <inertial>
          <mass value="0.000001" />
          <origin xyz="0.0 0.0 0.0" rpy="0 0 0" />
          <inertia ixx="0.000001" ixy="0" ixz="0" iyy="0.000001" iyz="0" izz="0.000001" />
      </inertial>
  </link>
  <joint name="lin_x_joint" type="fixed">
    <origin rpy="0 0 0" xyz="0 0 0"/>
    <axis xyz="1 0 0"/>
    <limit effort="1000.0" lower="-1e+16" upper="1e+16" velocity="3.5"/>
    <joint_properties damping="1" friction="1"/>
    <parent link="world"/>
    <child link="lin_x_link"/>
  </joint>
  <link name="lin_x_link">
      <inertial>
          <mass value="0.000001" />
          <origin xyz="0.0 0.0 0.0" rpy="0 0 0" />
          <inertia ixx="0.000001" ixy="0" ixz="0" iyy="0.000001" iyz="0" izz="0.000001" />
      </inertial>
  </link>
  <joint name="lin_y_joint" type="fixed">
    <origin rpy="0 0 0" xyz="0 0 0"/>
    <axis xyz="0 1 0"/>
    <limit effort="1000.0" lower="-1e+16" upper="1e+16" velocity="3.5"/>
    <joint_properties damping="1" friction="1"/>
    <parent link="lin_x_link"/>
    <child link="lin_y_link"/>
  </joint>
  <link name="lin_y_link">
      <inertial>
          <mass value="0.000001" />
          <origin xyz="0.0 0.0 0.0" rpy="0 0 0" />
          <inertia ixx="0.000001" ixy="0" ixz="0" iyy="0.000001" iyz="0" izz="0.000001" />
      </inertial>
  </link>
  <joint name="rot_z_joint" type="fixed">
    <origin rpy="0 0 0" xyz="0 0 0"/>
    <axis xyz="0 0 1"/>
    <limit effort="1000.0" lower="-1e+16" upper="1e+16" velocity="3.5"/>
    <joint_properties damping="1" friction="1"/>
    <parent link="lin_y_link"/>
    <child link="base_link"/>
  </joint>
  <link name="base_link">
      <inertial>
          <mass value="0.000001" />
          <origin xyz="0.0 0.0 0.0" rpy="0 0 0" />
          <inertia ixx="0.000001" ixy="0" ixz="0" iyy="0.000001" iyz="0" izz="0.000001" />
      </inertial>
  </link>
  <joint name="base_footprint_joint" type="fixed">
    <origin rpy="0 0 0" xyz="0 0 0"/>
    <axis xyz="0 0 -1"/>
    <joint_properties damping="1" friction="1"/>
    <parent link="base_link"/>
    <child link="base_footprint"/>
  </joint>
  <link name="base_footprint">
    <inertial>
      <mass value="64"/>
      <origin xyz="0 0.0 0.0"/>
      <inertia ixx="2.8" ixy="0.0" ixz="0.0" iyy="2.8" iyz="0.0" izz="2.8"/>
    </inertial>
    <visual>
      <origin rpy="-1.571 0 1.571" xyz="0. 0. 0"/>
      <geometry>
        <mesh filename="mmo500_description/meshes/MPO-500-BODY.dae" scale="0.001 0.001 0.001"/>
      </geometry>
    </visual>
    <collision>
      <origin rpy="-1.571 0 1.571" xyz="0. 0. 0.0"/>
      <geometry>
        <!--<box size="0.68 0.41 0.25"/> -->
        <mesh filename="mmo500_description/meshes/MPO-500-BODY.dae" scale="0.001 0.001 0.001"/>
      </geometry>
    </collision>
  </link>
  <joint name="mpo_500_omni_wheel_front_left_joint" type="fixed">
    <origin rpy="0 0 0" xyz="0.25 0.28 0.13"/>
    <axis xyz="0 1 0"/>
    <joint_properties damping="100" friction="100"/>
    <parent link="base_footprint"/>
    <child link="mpo_500_omni_wheel_front_left_link"/>
  </joint>
  <link name="mpo_500_omni_wheel_front_left_link" type="wheel">
    <inertial>
      <mass value="4.2"/>
      <origin rpy="0 0 0" xyz="0 0 0"/>
      <inertia ixx="0.0338" ixy="0.0" ixz="0.0" iyy="0.0338" iyz="0.0" izz="0.0338"/>
    </inertial>
    <visual>
      <origin rpy="0 0 0" xyz="0 0 0"/>
      <geometry>
        <mesh filename="mmo500_description/meshes/MPO-500-WHEEL.dae" scale="0.001 0.001 0.001"/>
      </geometry>
    </visual>
    <collision>
      <origin rpy="1.57 0 0" xyz="0 0 0"/>
      <geometry>
        <sphere radius="0.127"/>
      </geometry>
    </collision>
  </link>
  <joint name="mpo_500_omni_wheel_front_right_joint" type="fixed">
    <origin rpy="0 0 3.14" xyz="0.25 -0.28 0.13"/>
    <axis xyz="0 1 0"/>
    <joint_properties damping="100" friction="100"/>
    <parent link="base_footprint"/>
    <child link="mpo_500_omni_wheel_front_right_link"/>
  </joint>
  <link name="mpo_500_omni_wheel_front_right_link" type="wheel">
    <inertial>
      <mass value="4.2"/>
      <origin rpy="0 0 0" xyz="0 0 0"/>
      <inertia ixx="0.0338" ixy="0.0" ixz="0.0" iyy="0.0338" iyz="0.0" izz="0.0338"/>
    </inertial>
    <visual>
      <origin rpy="0 0 0" xyz="0 0 0"/>
      <geometry>
        <mesh filename="mmo500_description/meshes/MPO-500-WHEEL.dae" scale="0.001 0.001 0.001"/>
      </geometry>
    </visual>
    <collision>
      <origin rpy="1.57 0 0" xyz="0 0 0"/>
      <geometry>
        <sphere radius="0.127"/>
      </geometry>
    </collision>
  </link>
  <joint name="mpo_500_omni_wheel_back_left_joint" type="fixed">
    <origin rpy="0 0 0" xyz="-0.25 0.28 0.13"/>
    <axis xyz="0 1 0"/>
    <joint_properties damping="100" friction="100"/>
    <parent link="base_footprint"/>
    <child link="mpo_500_omni_wheel_back_left_link"/>
  </joint>
  <link name="mpo_500_omni_wheel_back_left_link" type="wheel">
    <inertial>
      <mass value="4.2"/>
      <origin rpy="0 0 0" xyz="0 0 0"/>
      <inertia ixx="0.0338" ixy="0.0" ixz="0.0" iyy="0.0338" iyz="0.0" izz="0.0338"/>
    </inertial>
    <visual>
      <origin rpy="0 0 0" xyz="0 0 0"/>
      <geometry>
        <mesh filename="mmo500_description/meshes/MPO-500-WHEEL.dae" scale="0.001 0.001 0.001"/>
      </geometry>
    </visual>
    <collision>
      <origin rpy="1.57 0 0" xyz="0 0 0"/>
      <geometry>
        <sphere radius="0.127"/>
      </geometry>
    </collision>
  </link>
  <joint name="mpo_500_omni_wheel_back_right_joint" type="fixed">
    <origin rpy="0 0 3.14" xyz="-0.25 -0.28 0.13"/>
    <axis xyz="0 1 0"/>
    <joint_properties damping="100" friction="100"/>
    <parent link="base_footprint"/>
    <child link="mpo_500_omni_wheel_back_right_link"/>
  </joint>
  <link name="mpo_500_omni_wheel_back_right_link" type="wheel">
    <inertial>
      <mass value="4.2"/>
      <origin rpy="0 0 0" xyz="0 0 0"/>
      <inertia ixx="0.0338" ixy="0.0" ixz="0.0" iyy="0.0338" iyz="0.0" izz="0.0338"/>
    </inertial>
    <visual>
      <origin rpy="0 0 0" xyz="0 0 0"/>
      <geometry>
        <mesh filename="mmo500_description/meshes/MPO-500-WHEEL.dae" scale="0.001 0.001 0.001"/>
      </geometry>
    </visual>
    <collision>
      <origin rpy="1.57 0 0" xyz="0 0 0"/>
      <geometry>
        <sphere radius="0.127"/>
      </geometry>
    </collision>
  </link>
  <joint name="lidar_1_joint" type="fixed">
    <axis xyz="0 1 0"/>
    <origin rpy="0 0 0" xyz="0.442 0 0.372"/>
    <parent link="base_link"/>
    <child link="lidar_1_link"/>
  </joint>
  <link name="lidar_1_link" type="laser">
    <inertial>
      <mass value="0.0001"/>
      <origin rpy="0 0 0" xyz="0 0 0"/>
      <inertia ixx="0.0001" ixy="0" ixz="0" iyy="0.000001" iyz="0" izz="0.0001"/>
    </inertial>
    <visual>
      <origin rpy="1.57 0 0" xyz="0 0 -0.06"/>
      <geometry>
        <mesh filename="mmo500_description/meshes/SICK-MICROSCAN3.dae" scale="0.001 0.001 0.001"/>
      </geometry>
    </visual>
    <collision>
      <origin rpy="1.57 0 0" xyz="0 0 -0.06"/>
      <geometry>
        <mesh filename="mmo500_description/meshes/SICK-MICROSCAN3.dae" scale="0.001 0.001 0.001"/>
      </geometry>
    </collision>
  </link>
  <joint name="lidar_2_joint" type="fixed">
    <axis xyz="0 1 0"/>
    <origin rpy="0 0 3.14" xyz="-0.442 0 0.372"/>
    <parent link="base_link"/>
    <child link="lidar_2_link"/>
  </joint>
  <link name="lidar_2_link" type="laser">
    <inertial>
      <mass value="0.0001"/>
      <origin rpy="0 0 0" xyz="0 0 0"/>
      <inertia ixx="0.0001" ixy="0" ixz="0" iyy="0.000001" iyz="0" izz="0.0001"/>
    </inertial>
    <visual>
      <origin rpy="1.57 0 0" xyz="0 0 -0.06"/>
      <geometry>
        <mesh filename="mmo500_description/meshes/SICK-MICROSCAN3.dae" scale="0.001 0.001 0.001"/>
      </geometry>
    </visual>
    <collision>
      <origin rpy="1.57 0 0" xyz="0 0 -0.06"/>
      <geometry>
        <mesh filename="mmo500_description/meshes/SICK-MICROSCAN3.dae" scale="0.001 0.001 0.001"/>
      </geometry>
    </collision>
  </link>

  <joint name="cabinet_joint" type="fixed">
    <origin rpy="0 0 0" xyz="0.072 0 0.386"/>
    <joint_properties damping="1" friction="1"/>
    <parent link="base_link"/>
    <child link="cabinet_link"/>
  </joint>
  <link name="cabinet_link">
    <inertial>
      <mass value="2"/>
      <origin rpy="0 0 0" xyz="0 0 0"/>
      <inertia ixx="0.457072" ixy="0.0" ixz="0.0" iyy="0.23616" iyz="0.0" izz="0.686"/>
    </inertial>
    <visual>
      <origin rpy="0 0 -1.5708" xyz="0 0 0"/>
      <geometry>
        <mesh filename="mmo500_description/meshes/cabin.dae" scale="0.001 0.001 0.001"/>
      </geometry>
    </visual>
    <collision>
      <origin rpy="0 0 0" xyz="0. 0. 0"/>
      <geometry>
        <mesh filename="mmo500_description/meshes/cabin.dae" scale="0.001 0.001 0.001"/>
      </geometry>
    </collision>
  </link>
  <joint name="cabinet_u10_joint" type="fixed">
    <parent link="cabinet_link"/>
    <child link="ur10_base_link"/>
    <origin rpy="0.0 0.0 0.0" xyz="0.133 0.0 0.416"/>
  </joint>
  <link name="ur10_base_link">
    <visual>
      <geometry>
        <mesh filename="mmo500_description/meshes/base.dae"/>
      </geometry>
    </visual>
    <collision>
      <geometry>
        <mesh filename="mmo500_description/meshes/base.dae"/>
      </geometry>
    </collision>
    <inertial>
      <mass value="2.0"/>
      <origin rpy="0 0 0" xyz="0.0 0.0 0.0"/>
      <inertia ixx="0.0030531654454" ixy="0.0" ixz="0.0" iyy="0.0030531654454" iyz="0.0" izz="0.005625"/>
    </inertial>
  </link>
  <joint name="shoulder_pan_joint" type="revolute">
    <parent link="ur10_base_link"/>
    <child link="shoulder_link"/>
    <origin rpy="0.0 0.0 0.0" xyz="0.0 0.0 0.1273"/>
    <axis xyz="0 0 1"/>
    <limit effort="330.0" lower="-6.28318530718" upper="6.28318530718" velocity="2.16"/>
    <dynamics damping="0.5" friction="10.0"/>
  </joint>
  <link name="shoulder_link">
    <visual>
      <geometry>
        <mesh filename="mmo500_description/meshes/shoulder.dae"/>
      </geometry>
    </visual>
    <collision>
      <geometry>
        <mesh filename="mmo500_description/meshes/shoulder.dae"/>
      </geometry>
    </collision>
    <inertial>
      <mass value="7.778"/>
      <origin rpy="0 0 0" xyz="0.0 0.0 0.0"/>
      <inertia ixx="0.0314743125769" ixy="0.0" ixz="0.0" iyy="0.0314743125769" iyz="0.0" izz="0.021875625"/>
    </inertial>
  </link>
  <joint name="shoulder_lift_joint" type="revolute">
    <parent link="shoulder_link"/>
    <child link="upper_arm_link"/>
    <origin rpy="0.0 -1.25 0.0" xyz="0.0 0.220941 0.0"/>
    <axis xyz="0 1 0"/>
    <limit effort="330.0" lower="-3.14159265359" upper="3.14159265359" velocity="2.16"/>
    <dynamics damping="0.5" friction="10.0"/>
  </joint>
  <link name="upper_arm_link">
    <visual>
      <geometry>
        <mesh filename="mmo500_description/meshes/upperarm.dae"/>
      </geometry>
    </visual>
    <collision>
      <geometry>
        <mesh filename="mmo500_description/meshes/upperarm.dae"/>
      </geometry>
    </collision>
    <inertial>
      <mass value="12.93"/>
      <origin rpy="0 0 0" xyz="0.0 0.0 0.306"/>
      <inertia ixx="0.421753803798" ixy="0.0" ixz="0.0" iyy="0.421753803798" iyz="0.0" izz="0.036365625"/>
    </inertial>
  </link>
  <joint name="elbow_joint" type="revolute">
    <parent link="upper_arm_link"/>
    <child link="forearm_link"/>
    <origin rpy="0.0 -1.95 0.0" xyz="0.0 -0.1719 0.612"/>
    <axis xyz="0 1 0"/>
    <limit effort="150.0" lower="-3.14159265359" upper="3.14159265359" velocity="3.15"/>
    <dynamics damping="0.5" friction="10.0"/>
  </joint>
  <link name="forearm_link">
    <visual>
      <geometry>
        <mesh filename="mmo500_description/meshes/forearm.dae"/>
      </geometry>
    </visual>
    <collision>
      <geometry>
        <mesh filename="mmo500_description/meshes/forearm.dae"/>
      </geometry>
    </collision>
    <inertial>
      <mass value="3.87"/>
      <origin rpy="0 0 0" xyz="0.0 0.0 0.28615"/>
      <inertia ixx="0.111069694097" ixy="0.0" ixz="0.0" iyy="0.111069694097" iyz="0.0" izz="0.010884375"/>
    </inertial>
  </link>
  <joint name="wrist_1_joint" type="revolute">
    <parent link="forearm_link"/>
    <child link="wrist_1_link"/>
    <origin rpy="0.0 1.57079632679 0.0" xyz="0.0 0.0 0.5723"/>
    <axis xyz="0 1 0"/>
    <limit effort="54.0" lower="-3.14159265359" upper="3.14159265359" velocity="3.2"/>
    <dynamics damping="0.5" friction="10.0"/>
  </joint>
  <link name="wrist_1_link">
    <visual>
      <geometry>
        <mesh filename="mmo500_description/meshes/wrist1.dae"/>
      </geometry>
    </visual>
    <collision>
      <geometry>
        <mesh filename="mmo500_description/meshes/wrist1.dae"/>
      </geometry>
    </collision>
    <inertial>
      <mass value="1.96"/>
      <origin rpy="0 0 0" xyz="0.0 0.0 0.0"/>
      <inertia ixx="0.0051082479567" ixy="0.0" ixz="0.0" iyy="0.0051082479567" iyz="0.0" izz="0.0055125"/>
    </inertial>
  </link>
  <joint name="wrist_2_joint" type="revolute">
    <parent link="wrist_1_link"/>
    <child link="wrist_2_link"/>
    <origin rpy="0.0 0.0 0.0" xyz="0.0 0.1149 0.0"/>
    <axis xyz="0 0 1"/>
    <limit effort="54.0" lower="-3.14159265359" upper="3.14159265359" velocity="3.2"/>
    <dynamics damping="0.5" friction="10.0"/>
  </joint>
  <link name="wrist_2_link">
    <visual>
      <geometry>
        <mesh filename="mmo500_description/meshes/wrist2.dae"/>
      </geometry>
    </visual>
    <collision>
      <geometry>
        <mesh filename="mmo500_description/meshes/wrist2.dae"/>
      </geometry>
    </collision>
    <inertial>
      <mass value="1.96"/>
      <origin rpy="0 0 0" xyz="0.0 0.0 0.0"/>
      <inertia ixx="0.0051082479567" ixy="0.0" ixz="0.0" iyy="0.0051082479567" iyz="0.0" izz="0.0055125"/>
    </inertial>
  </link>
  <joint name="wrist_3_joint" type="revolute">
    <parent link="wrist_2_link"/>
    <child link="wrist_3_link"/>
    <origin rpy="0.0 0.0 0.0" xyz="0.0 0.0 0.1157"/>
    <axis xyz="0 1 0"/>
    <limit effort="54.0" lower="-3.14159265359" upper="3.14159265359" velocity="3.2"/>
    <dynamics damping="0.5" friction="10.0"/>
  </joint>
  <link name="wrist_3_link">
    <visual>
      <geometry>
        <mesh filename="mmo500_description/meshes/wrist3.dae"/>
      </geometry>
    </visual>
    <collision>
      <geometry>
        <mesh filename="mmo500_description/meshes/wrist3.dae"/>
      </geometry>
    </collision>
    <inertial>
      <mass value="0.202"/>
      <origin rpy="0 0 0" xyz="0.0 0.0 0.0"/>
      <inertia ixx="0.000526462289415" ixy="0.0" ixz="0.0" iyy="0.000526462289415" iyz="0.0" izz="0.000568125"/>
    </inertial>
  </link>
  <joint name="ee_fixed_joint" type="fixed">
    <parent link="wrist_3_link"/>
    <child link="ee_link"/>
    <origin rpy="0.0 0.0 1.57079632679" xyz="0.0 0.0922 0.0"/>
  </joint>
  <link name="ee_link">
      <inertial>
          <mass value="0.000001" />
          <origin xyz="0.0 0.0 0.0" rpy="0 0 0" />
          <inertia ixx="0.000001" ixy="0" ixz="0" iyy="0.000001" iyz="0" izz="0.000001" />
      </inertial>
    <collision>
      <geometry>
        <box size="0.01 0.01 0.01"/>
      </geometry>
      <origin rpy="0 0 0" xyz="-0.01 0 0"/>
    </collision>
  </link>

  <!-- nothing to do here at the moment -->
  <!-- ROS ur10_base_link to UR 'Base' Coordinates transform -->
  <link name="base">
      <inertial>
          <mass value="0.000001" />
          <origin xyz="0.0 0.0 0.0" rpy="0 0 0" />
          <inertia ixx="0.000001" ixy="0" ixz="0" iyy="0.000001" iyz="0" izz="0.000001" />
      </inertial>
  </link>
  <joint name="ur10_base_link-base_fixed_joint" type="fixed">
    <!-- NOTE: this rotation is only needed as long as ur10_base_link itself is
                 not corrected wrt the real robot (ie: rotated over 180
                 degrees)
      -->
    <origin rpy="0 0 -3.14159265359" xyz="0 0 0"/>
    <parent link="ur10_base_link"/>
    <child link="base"/>
  </joint>
  <!-- Frame coincident with all-zeros TCP on UR controller -->
  <link name="tool0">
      <inertial>
          <mass value="0.000001" />
          <origin xyz="0.0 0.0 0.0" rpy="0 0 0" />
          <inertia ixx="0.000001" ixy="0" ixz="0" iyy="0.000001" iyz="0" izz="0.000001" />
      </inertial>
  </link>
  <joint name="wrist_3_link-tool0_fixed_joint" type="fixed">
    <origin rpy="-1.57079632679 0 0" xyz="0 0.0922 0"/>
    <parent link="wrist_3_link"/>
    <child link="tool0"/>
  </joint>
  <link name="H1_base_attach">
      <inertial>
          <mass value="0.000001" />
          <origin xyz="0.0 0.0 0.0" rpy="0 0 0" />
          <inertia ixx="0.000001" ixy="0" ixz="0" iyy="0.000001" iyz="0" izz="0.000001" />
      </inertial>
  </link>
  <material name="Blue">
    <color rgba="0.0 0.0 0.8 1.0"/>
  </material>
  <material name="Green">
    <color rgba="0.0 0.8 0.0 1.0"/>
  </material>
  <material name="BiotacGreen">
    <color rgba="0.31 0.85 0.42 1.0"/>
  </material>
  <material name="Grey">
    <color rgba="0.2 0.2 0.2 1.0"/>
  </material>
  <material name="LightGrey">
    <color rgba="0.6 0.6 0.6 1.0"/>
  </material>
  <material name="Red">
    <color rgba="0.8 0.0 0.0 1.0"/>
  </material>
  <material name="White">
    <color rgba="1.0 1.0 1.0 1.0"/>
  </material>
  <link name="H1_ur10_base_link">
    <inertial>
      <origin rpy="0 0 0" xyz="-8.6116E-06 -0.0058125 0.028294"/>
      <mass value="0.07527"/>
      <inertia ixx="0.00014442" ixy="1.2033E-08" ixz="-5.9646E-10" iyy="0.00014979" iyz="-1.0288E-05" izz="5.2943E-05"/>
    </inertial>
    <visual>
      <origin rpy="0 0 0" xyz="0 0 0"/>
      <geometry>
        <mesh filename="mmo500_description/meshes/palm_link_simple.dae"/>
      </geometry>
      <material name="light_grey">
        <color rgba="0.75 0.75 0.75 1.0"/>
      </material>
    </visual>
    <collision>
      <origin rpy="0 0 0" xyz="0 0 0"/>
      <geometry>
        <mesh filename="mmo500_description/meshes/palm_link_simple.dae"/>
      </geometry>
      <material name="light_grey">
        <color rgba="0.75 0.75 0.75 1.0"/>
      </material>
    </collision>
  </link>
  <joint name="H1Base" type="fixed">
    <origin rpy="0 0 0" xyz="0 0 0"/>
    <parent link="H1_base_attach"/>
    <child link="H1_wrist_attach"/>
  </joint>
  <link name="H1_insert_F1">
      <inertial>
          <mass value="0.000001" />
          <origin xyz="0.0 0.0 0.0" rpy="0 0 0" />
          <inertia ixx="0.000001" ixy="0" ixz="0" iyy="0.000001" iyz="0" izz="0.000001" />
      </inertial>
  </link>
  <joint name="H1_dummy_joint_1" type="fixed">
    <origin rpy="0 0 2.3562" xyz="-0.045 -0.025981 0"/>
    <axis xyz="0 -1 0"/>
    <parent link="H1_ur10_base_link"/>
    <child link="H1_insert_F1"/>
  </joint>
  <link name="H1_insert_F2">
      <inertial>
          <mass value="0.000001" />
          <origin xyz="0.0 0.0 0.0" rpy="0 0 0" />
          <inertia ixx="0.000001" ixy="0" ixz="0" iyy="0.000001" iyz="0" izz="0.000001" />
      </inertial>
  </link>
  <joint name="H1_dummy_joint_2" type="fixed">
    <origin rpy="0 0 0" xyz="0 0.029019 0"/>
    <axis xyz="0 -1 0"/>
    <parent link="H1_ur10_base_link"/>
    <child link="H1_insert_F2"/>
  </joint>
  <link name="H1_insert_F3">
      <inertial>
          <mass value="0.000001" />
          <origin xyz="0.0 0.0 0.0" rpy="0 0 0" />
          <inertia ixx="0.000001" ixy="0" ixz="0" iyy="0.000001" iyz="0" izz="0.000001" />
      </inertial>
  </link>
  <joint name="H1_dummy_joint_3" type="fixed">
    <origin rpy="0 0 -2.3562" xyz="0.045 -0.025981 0"/>
    <axis xyz="0 -1 0"/>
    <parent link="H1_ur10_base_link"/>
    <child link="H1_insert_F3"/>
  </joint>
  <link name="H1_wrist_attach">
      <inertial>
          <mass value="0.000001" />
          <origin xyz="0.0 0.0 0.0" rpy="0 0 0" />
          <inertia ixx="0.000001" ixy="0" ixz="0" iyy="0.000001" iyz="0" izz="0.000001" />
      </inertial>
  </link>
  <joint name="H1_ur10_base_link_wrist_attach" type="fixed">
    <origin rpy="0 0 0" xyz="0 0 -0.0005"/>
    <child link="H1_ur10_base_link"/>
    <parent link="H1_wrist_attach"/>
  </joint>
  <link name="H1_F1_palm_link">
    <inertial>
      <origin rpy="0 0 0" xyz="-0.00681802120880393 -0.00947020456878004 0.067587996682422"/>
      <mass value="0.0341482312344481"/>
      <inertia ixx="2.79747833772125E-05" ixy="-5.50900644725373E-08" ixz="-2.82072424927723E-07" iyy="2.67800858812928E-05" iyz="3.1953125069394E-06" izz="9.86122271726361E-06"/>
    </inertial>
    <visual>
      <origin rpy="0 0 0" xyz="0 0 0"/>
      <geometry>
        <mesh filename="mmo500_description/meshes/finger_palm_link.dae"/>
      </geometry>
      <material name="light_grey">
        <color rgba="0.75 0.75 0.75 1.0"/>
      </material>
    </visual>
    <!-- Collision mesh no needed as it is part of palm_link_simple.dae collision mesh -->
    <!--xacro:mesh_collision file_name="finger_palm_link.dae">
        <origin xyz="0 0 0" rpy="0 0 0" />
        <xacro:light_grey/>
      </xacro:mesh_collision-->
  </link>
  <link name="H1_F1_ur10_base_link">
    <inertial>
      <origin rpy="0 0 0" xyz="-0.000142856770000038 0.0265691681336443 0.0538751581621436"/>
      <mass value="0.174652229503358"/>
      <inertia ixx="0.000298372741514267" ixy="-5.05751882577435E-07" ixz="1.94982779411417E-07" iyy="0.000299629589232877" iyz="2.79565205733806E-05" izz="0.000134889645145365"/>
    </inertial>
    <visual>
      <origin rpy="0 0 0" xyz="0 0 0"/>
      <geometry>
        <mesh filename="mmo500_description/meshes/finger_base_link_simple.dae"/>
      </geometry>
      <material name="light_grey">
        <color rgba="0.75 0.75 0.75 1.0"/>
      </material>
    </visual>
    <collision>
      <origin rpy="0 0 0" xyz="0 0 0"/>
      <geometry>
        <mesh filename="mmo500_description/meshes/finger_base_link_simple.dae"/>
      </geometry>
      <material name="light_grey">
        <color rgba="0.75 0.75 0.75 1.0"/>
      </material>
    </collision>
  </link>
  <link name="H1_F1_link_1">
    <inertial>
      <origin rpy="0 0 0" xyz="-0.000141876508729455 -0.00135409566494088 0.0277606215980989"/>
      <mass value="0.0827759744227546"/>
      <inertia ixx="4.61070151157777E-05" ixy="7.47741111557837E-08" ixz="-2.25165057702697E-07" iyy="5.27678327317508E-05" iyz="-3.64603343546298E-07" izz="2.89599551320955E-05"/>
    </inertial>
    <visual>
      <origin rpy="0 0 0" xyz="0 0 0"/>
      <geometry>
        <mesh filename="mmo500_description/meshes/finger_prox_link_simple.dae"/>
      </geometry>
      <material name="light_grey">
        <color rgba="0.75 0.75 0.75 1.0"/>
      </material>
    </visual>
    <collision>
      <origin rpy="0 0 0" xyz="0 0 0"/>
      <geometry>
        <mesh filename="mmo500_description/meshes/finger_prox_link_simple.dae"/>
      </geometry>
      <material name="light_grey">
        <color rgba="0.75 0.75 0.75 1.0"/>
      </material>
    </collision>
  </link>
  <link name="H1_F1_link_2">
    <inertial>
      <origin rpy="0 0 0" xyz="0.000506812071918918 -0.00091292934992606 0.0156620851768385"/>
      <mass value="0.0270049614151599"/>
      <inertia ixx="1.06942730265546E-05" ixy="-7.1810089794211E-09" ixz="-3.49957211410822E-07" iyy="1.05772889540593E-05" iyz="-8.38595987731518E-07" izz="3.27173446995846E-06"/>
    </inertial>
    <visual>
      <origin rpy="0 0 0" xyz="0 0 0"/>
      <geometry>
        <mesh filename="mmo500_description/meshes/finger_dist_link_simple.dae"/>
      </geometry>
      <material name="light_grey">
        <color rgba="0.75 0.75 0.75 1.0"/>
      </material>
    </visual>
    <collision>
      <origin rpy="0 0 0" xyz="0 0 0"/>
      <geometry>
        <mesh filename="mmo500_description/meshes/finger_dist_link_simple.dae"/>
      </geometry>
      <material name="light_grey">
        <color rgba="0.75 0.75 0.75 1.0"/>
      </material>
    </collision>
  </link>
  <joint name="H1_F1Palm" type="fixed">
    <origin rpy="0 0 0" xyz="0 0 0"/>
    <parent link="H1_insert_F1"/>
    <child link="H1_F1_palm_link"/>
  </joint>
  <joint name="H1_F1J1" type="fixed">
    <origin rpy="-8.8818E-16 -1.0061E-16 0.022402" xyz="0 0 0.00016528"/>
    <axis xyz="0 0 1"/>
    <parent link="H1_F1_palm_link"/>
    <child link="H1_F1_ur10_base_link"/>
    <limit effort="50" lower="-0.785398163397" upper="0.785398163397" velocity="1.0"/>
    <dynamics damping="0.0" friction="10.0"/>
  </joint>
  <joint name="H1_F1J2" type="fixed">
    <origin rpy="0.070695 6.9389E-16 2.0947E-16" xyz="0 0.035 0.11683"/>
    <axis xyz="1 0 0"/>
    <parent link="H1_F1_ur10_base_link"/>
    <child link="H1_F1_link_1"/>
    <limit effort="50" lower="-1.3962634016" upper="1.0471975512" velocity="1.0"/>
    <dynamics damping="0.0" friction="10.0"/>
  </joint>
  <joint name="H1_F1J3" type="fixed">
    <origin rpy="-0.0068649 1.7347E-18 1.6176E-16" xyz="0 0 0.06"/>
    <axis xyz="1 0 0"/>
    <parent link="H1_F1_link_1"/>
    <child link="H1_F1_link_2"/>
    <limit effort="50" lower="-1.0471975512" upper="1.57079632679" velocity="1.0"/>
    <dynamics damping="0.0" friction="10.0"/>
  </joint>

  <!-- finger tip -->
  <link name="H1_F1_tip">
    <inertial>
      <origin rpy="0 0 0" xyz="-0.000925580990320645 -0.00495543398528436 0.0355865585792753"/>
      <mass value="0.00906322686585137"/>
      <inertia ixx="1.10049088227995E-06" ixy="-3.7290982171096E-09" ixz="-9.54389365908683E-09" iyy="1.36130530510584E-06" iyz="6.66133713720777E-08" izz="6.42259773618367E-07"/>
    </inertial>
    <visual>
      <origin rpy="0 0 0" xyz="0 0 0"/>
      <geometry>
        <mesh filename="mmo500_description/meshes/omd-d18-tip.dae"/>
      </geometry>
      <material name="light_grey">
        <color rgba="0.75 0.75 0.75 1.0"/>
      </material>
    </visual>
    <collision>
      <origin rpy="0 0 0" xyz="0 0 0"/>
      <geometry>
        <mesh filename="mmo500_description/meshes/omd-d18-tip.dae"/>
      </geometry>
      <material name="light_grey">
        <color rgba="0.75 0.75 0.75 1.0"/>
      </material>
    </collision>
  </link>
  <link name="H1_F1_optoforce">
      <inertial>
          <mass value="0.000001" />
          <origin xyz="0.0 0.0 0.0" rpy="0 0 0" />
          <inertia ixx="0.000001" ixy="0" ixz="0" iyy="0.000001" iyz="0" izz="0.000001" />
      </inertial>
  </link>
  <joint name="H1_F1_tip_to_optoforce" type="fixed">
    <parent link="H1_F1_tip"/>
    <child link="H1_F1_optoforce"/>
    <origin rpy="-0.35 0 0" xyz="0 -0.006 0.046"/>
  </joint>
  <joint name="H1_F1_tip" type="fixed">
    <parent link="H1_F1_link_2"/>
    <child link="H1_F1_tip"/>
  </joint>
  <link name="H1_F2_palm_link">
    <inertial>
      <origin rpy="0 0 0" xyz="-0.00681802120880393 -0.00947020456878004 0.067587996682422"/>
      <mass value="0.0341482312344481"/>
      <inertia ixx="2.79747833772125E-05" ixy="-5.50900644725373E-08" ixz="-2.82072424927723E-07" iyy="2.67800858812928E-05" iyz="3.1953125069394E-06" izz="9.86122271726361E-06"/>
    </inertial>
    <visual>
      <origin rpy="0 0 0" xyz="0 0 0"/>
      <geometry>
        <mesh filename="mmo500_description/meshes/finger_palm_link.dae"/>
      </geometry>
      <material name="light_grey">
        <color rgba="0.75 0.75 0.75 1.0"/>
      </material>
    </visual>
    <!-- Collision mesh no needed as it is part of palm_link_simple.dae collision mesh -->
    <!--xacro:mesh_collision file_name="finger_palm_link.dae">
        <origin xyz="0 0 0" rpy="0 0 0" />
        <xacro:light_grey/>
      </xacro:mesh_collision-->
  </link>
  <link name="H1_F2_ur10_base_link">
    <inertial>
      <origin rpy="0 0 0" xyz="-0.000142856770000038 0.0265691681336443 0.0538751581621436"/>
      <mass value="0.174652229503358"/>
      <inertia ixx="0.000298372741514267" ixy="-5.05751882577435E-07" ixz="1.94982779411417E-07" iyy="0.000299629589232877" iyz="2.79565205733806E-05" izz="0.000134889645145365"/>
    </inertial>
    <visual>
      <origin rpy="0 0 0" xyz="0 0 0"/>
      <geometry>
        <mesh filename="mmo500_description/meshes/finger_base_link_simple.dae"/>
      </geometry>
      <material name="light_grey">
        <color rgba="0.75 0.75 0.75 1.0"/>
      </material>
    </visual>
    <collision>
      <origin rpy="0 0 0" xyz="0 0 0"/>
      <geometry>
        <mesh filename="mmo500_description/meshes/finger_base_link_simple.dae"/>
      </geometry>
      <material name="light_grey">
        <color rgba="0.75 0.75 0.75 1.0"/>
      </material>
    </collision>
  </link>
  <link name="H1_F2_link_1">
    <inertial>
      <origin rpy="0 0 0" xyz="-0.000141876508729455 -0.00135409566494088 0.0277606215980989"/>
      <mass value="0.0827759744227546"/>
      <inertia ixx="4.61070151157777E-05" ixy="7.47741111557837E-08" ixz="-2.25165057702697E-07" iyy="5.27678327317508E-05" iyz="-3.64603343546298E-07" izz="2.89599551320955E-05"/>
    </inertial>
    <visual>
      <origin rpy="0 0 0" xyz="0 0 0"/>
      <geometry>
        <mesh filename="mmo500_description/meshes/finger_prox_link_simple.dae"/>
      </geometry>
      <material name="light_grey">
        <color rgba="0.75 0.75 0.75 1.0"/>
      </material>
    </visual>
    <collision>
      <origin rpy="0 0 0" xyz="0 0 0"/>
      <geometry>
        <mesh filename="mmo500_description/meshes/finger_prox_link_simple.dae"/>
      </geometry>
      <material name="light_grey">
        <color rgba="0.75 0.75 0.75 1.0"/>
      </material>
    </collision>
  </link>
  <link name="H1_F2_link_2">
    <inertial>
      <origin rpy="0 0 0" xyz="0.000506812071918918 -0.00091292934992606 0.0156620851768385"/>
      <mass value="0.0270049614151599"/>
      <inertia ixx="1.06942730265546E-05" ixy="-7.1810089794211E-09" ixz="-3.49957211410822E-07" iyy="1.05772889540593E-05" iyz="-8.38595987731518E-07" izz="3.27173446995846E-06"/>
    </inertial>
    <visual>
      <origin rpy="0 0 0" xyz="0 0 0"/>
      <geometry>
        <mesh filename="mmo500_description/meshes/finger_dist_link_simple.dae"/>
      </geometry>
      <material name="light_grey">
        <color rgba="0.75 0.75 0.75 1.0"/>
      </material>
    </visual>
    <collision>
      <origin rpy="0 0 0" xyz="0 0 0"/>
      <geometry>
        <mesh filename="mmo500_description/meshes/finger_dist_link_simple.dae"/>
      </geometry>
      <material name="light_grey">
        <color rgba="0.75 0.75 0.75 1.0"/>
      </material>
    </collision>
  </link>
  <joint name="H1_F2Palm" type="fixed">
    <origin rpy="0 0 0" xyz="0 0 0"/>
    <parent link="H1_insert_F2"/>
    <child link="H1_F2_palm_link"/>
  </joint>
  <joint name="H1_F2J1" type="fixed">
    <origin rpy="-8.8818E-16 -1.0061E-16 0.022402" xyz="0 0 0.00016528"/>
    <axis xyz="0 0 1"/>
    <parent link="H1_F2_palm_link"/>
    <child link="H1_F2_ur10_base_link"/>
    <limit effort="30" lower="-0.785398163397" upper="0.785398163397" velocity="1.0"/>
    <dynamics damping="0.0" friction="10.0"/>
  </joint>
  <joint name="H1_F2J2" type="fixed">
    <origin rpy="0.070695 6.9389E-16 2.0947E-16" xyz="0 0.035 0.11683"/>
    <axis xyz="1 0 0"/>
    <parent link="H1_F2_ur10_base_link"/>
    <child link="H1_F2_link_1"/>
    <limit effort="30" lower="-1.3962634016" upper="1.0471975512" velocity="1.0"/>
    <dynamics damping="0.0" friction="10.0"/>
  </joint>
  <joint name="H1_F2J3" type="fixed">
    <origin rpy="-0.0068649 1.7347E-18 1.6176E-16" xyz="0 0 0.06"/>
    <axis xyz="1 0 0"/>
    <parent link="H1_F2_link_1"/>
    <child link="H1_F2_link_2"/>
    <limit effort="30" lower="-1.0471975512" upper="1.57079632679" velocity="1.0"/>
    <dynamics damping="0.0" friction="10.0"/>
  </joint>

  <!-- finger tip -->
  <link name="H1_F2_tip">
    <inertial>
      <origin rpy="0 0 0" xyz="-0.000925580990320645 -0.00495543398528436 0.0355865585792753"/>
      <mass value="0.00906322686585137"/>
      <inertia ixx="1.10049088227995E-06" ixy="-3.7290982171096E-09" ixz="-9.54389365908683E-09" iyy="1.36130530510584E-06" iyz="6.66133713720777E-08" izz="6.42259773618367E-07"/>
    </inertial>
    <visual>
      <origin rpy="0 0 0" xyz="0 0 0"/>
      <geometry>
        <mesh filename="mmo500_description/meshes/omd-d18-tip.dae"/>
      </geometry>
      <material name="light_grey">
        <color rgba="0.75 0.75 0.75 1.0"/>
      </material>
    </visual>
    <collision>
      <origin rpy="0 0 0" xyz="0 0 0"/>
      <geometry>
        <mesh filename="mmo500_description/meshes/omd-d18-tip.dae"/>
      </geometry>
      <material name="light_grey">
        <color rgba="0.75 0.75 0.75 1.0"/>
      </material>
    </collision>
  </link>
  <link name="H1_F2_optoforce">
      <inertial>
          <mass value="0.000001" />
          <origin xyz="0.0 0.0 0.0" rpy="0 0 0" />
          <inertia ixx="0.000001" ixy="0" ixz="0" iyy="0.000001" iyz="0" izz="0.000001" />
      </inertial>
  </link>
  <joint name="H1_F2_tip_to_optoforce" type="fixed">
    <parent link="H1_F2_tip"/>
    <child link="H1_F2_optoforce"/>
    <origin rpy="-0.35 0 0" xyz="0 -0.006 0.046"/>
  </joint>
  <joint name="H1_F2_tip" type="fixed">
    <parent link="H1_F2_link_2"/>
    <child link="H1_F2_tip"/>
  </joint>
  <link name="H1_F3_palm_link">
    <inertial>
      <origin rpy="0 0 0" xyz="-0.00681802120880393 -0.00947020456878004 0.067587996682422"/>
      <mass value="0.0341482312344481"/>
      <inertia ixx="2.79747833772125E-05" ixy="-5.50900644725373E-08" ixz="-2.82072424927723E-07" iyy="2.67800858812928E-05" iyz="3.1953125069394E-06" izz="9.86122271726361E-06"/>
    </inertial>
    <visual>
      <origin rpy="0 0 0" xyz="0 0 0"/>
      <geometry>
        <mesh filename="mmo500_description/meshes/finger_palm_link.dae"/>
      </geometry>
      <material name="light_grey">
        <color rgba="0.75 0.75 0.75 1.0"/>
      </material>
    </visual>
    <!-- Collision mesh no needed as it is part of palm_link_simple.dae collision mesh -->
    <!--xacro:mesh_collision file_name="finger_palm_link.dae">
        <origin xyz="0 0 0" rpy="0 0 0" />
        <xacro:light_grey/>
      </xacro:mesh_collision-->
  </link>
  <link name="H1_F3_ur10_base_link">
    <inertial>
      <origin rpy="0 0 0" xyz="-0.000142856770000038 0.0265691681336443 0.0538751581621436"/>
      <mass value="0.174652229503358"/>
      <inertia ixx="0.000298372741514267" ixy="-5.05751882577435E-07" ixz="1.94982779411417E-07" iyy="0.000299629589232877" iyz="2.79565205733806E-05" izz="0.000134889645145365"/>
    </inertial>
    <visual>
      <origin rpy="0 0 0" xyz="0 0 0"/>
      <geometry>
        <mesh filename="mmo500_description/meshes/finger_base_link_simple.dae"/>
      </geometry>
      <material name="light_grey">
        <color rgba="0.75 0.75 0.75 1.0"/>
      </material>
    </visual>
    <collision>
      <origin rpy="0 0 0" xyz="0 0 0"/>
      <geometry>
        <mesh filename="mmo500_description/meshes/finger_base_link_simple.dae"/>
      </geometry>
      <material name="light_grey">
        <color rgba="0.75 0.75 0.75 1.0"/>
      </material>
    </collision>
  </link>
  <link name="H1_F3_link_1">
    <inertial>
      <origin rpy="0 0 0" xyz="-0.000141876508729455 -0.00135409566494088 0.0277606215980989"/>
      <mass value="0.0827759744227546"/>
      <inertia ixx="4.61070151157777E-05" ixy="7.47741111557837E-08" ixz="-2.25165057702697E-07" iyy="5.27678327317508E-05" iyz="-3.64603343546298E-07" izz="2.89599551320955E-05"/>
    </inertial>
    <visual>
      <origin rpy="0 0 0" xyz="0 0 0"/>
      <geometry>
        <mesh filename="mmo500_description/meshes/finger_prox_link_simple.dae"/>
      </geometry>
      <material name="light_grey">
        <color rgba="0.75 0.75 0.75 1.0"/>
      </material>
    </visual>
    <collision>
      <origin rpy="0 0 0" xyz="0 0 0"/>
      <geometry>
        <mesh filename="mmo500_description/meshes/finger_prox_link_simple.dae"/>
      </geometry>
      <material name="light_grey">
        <color rgba="0.75 0.75 0.75 1.0"/>
      </material>
    </collision>
  </link>
  <link name="H1_F3_link_2">
    <inertial>
      <origin rpy="0 0 0" xyz="0.000506812071918918 -0.00091292934992606 0.0156620851768385"/>
      <mass value="0.0270049614151599"/>
      <inertia ixx="1.06942730265546E-05" ixy="-7.1810089794211E-09" ixz="-3.49957211410822E-07" iyy="1.05772889540593E-05" iyz="-8.38595987731518E-07" izz="3.27173446995846E-06"/>
    </inertial>
    <visual>
      <origin rpy="0 0 0" xyz="0 0 0"/>
      <geometry>
        <mesh filename="mmo500_description/meshes/finger_dist_link_simple.dae"/>
      </geometry>
      <material name="light_grey">
        <color rgba="0.75 0.75 0.75 1.0"/>
      </material>
    </visual>
    <collision>
      <origin rpy="0 0 0" xyz="0 0 0"/>
      <geometry>
        <mesh filename="mmo500_description/meshes/finger_dist_link_simple.dae"/>
      </geometry>
      <material name="light_grey">
        <color rgba="0.75 0.75 0.75 1.0"/>
      </material>
    </collision>
  </link>
  <joint name="H1_F3Palm" type="fixed">
    <origin rpy="0 0 0" xyz="0 0 0"/>
    <parent link="H1_insert_F3"/>
    <child link="H1_F3_palm_link"/>
  </joint>
  <joint name="H1_F3J1" type="fixed">
    <origin rpy="-8.8818E-16 -1.0061E-16 0.022402" xyz="0 0 0.00016528"/>
    <axis xyz="0 0 1"/>
    <parent link="H1_F3_palm_link"/>
    <child link="H1_F3_ur10_base_link"/>
    <limit effort="30" lower="-0.785398163397" upper="0.785398163397" velocity="1.0"/>
    <dynamics damping="0.0" friction="10.0"/>
  </joint>
  <joint name="H1_F3J2" type="fixed">
    <origin rpy="0.070695 6.9389E-16 2.0947E-16" xyz="0 0.035 0.11683"/>
    <axis xyz="1 0 0"/>
    <parent link="H1_F3_ur10_base_link"/>
    <child link="H1_F3_link_1"/>
    <limit effort="30" lower="-1.3962634016" upper="1.0471975512" velocity="1.0"/>
    <dynamics damping="0.0" friction="10.0"/>
  </joint>
  <joint name="H1_F3J3" type="fixed">
    <origin rpy="-0.0068649 1.7347E-18 1.6176E-16" xyz="0 0 0.06"/>
    <axis xyz="1 0 0"/>
    <parent link="H1_F3_link_1"/>
    <child link="H1_F3_link_2"/>
    <limit effort="30" lower="-1.0471975512" upper="1.57079632679" velocity="1.0"/>
    <dynamics damping="0.0" friction="10.0"/>
  </joint>

  <!-- finger tip -->
  <link name="H1_F3_tip">
    <inertial>
      <origin rpy="0 0 0" xyz="-0.000925580990320645 -0.00495543398528436 0.0355865585792753"/>
      <mass value="0.00906322686585137"/>
      <inertia ixx="1.10049088227995E-06" ixy="-3.7290982171096E-09" ixz="-9.54389365908683E-09" iyy="1.36130530510584E-06" iyz="6.66133713720777E-08" izz="6.42259773618367E-07"/>
    </inertial>
    <visual>
      <origin rpy="0 0 0" xyz="0 0 0"/>
      <geometry>
        <mesh filename="mmo500_description/meshes/omd-d18-tip.dae"/>
      </geometry>
      <material name="light_grey">
        <color rgba="0.75 0.75 0.75 1.0"/>
      </material>
    </visual>
    <collision>
      <origin rpy="0 0 0" xyz="0 0 0"/>
      <geometry>
        <mesh filename="mmo500_description/meshes/omd-d18-tip.dae"/>
      </geometry>
      <material name="light_grey">
        <color rgba="0.75 0.75 0.75 1.0"/>
      </material>
    </collision>
  </link>
  <link name="H1_F3_optoforce">
      <inertial>
          <mass value="0.000001" />
          <origin xyz="0.0 0.0 0.0" rpy="0 0 0" />
          <inertia ixx="0.000001" ixy="0" ixz="0" iyy="0.000001" iyz="0" izz="0.000001" />
      </inertial>
  </link>
  <joint name="H1_F3_tip_to_optoforce" type="fixed">
    <parent link="H1_F3_tip"/>
    <child link="H1_F3_optoforce"/>
    <origin rpy="-0.35 0 0" xyz="0 -0.006 0.046"/>
  </joint>
  <joint name="H1_F3_tip" type="fixed">
    <parent link="H1_F3_link_2"/>
    <child link="H1_F3_tip"/>
  </joint>
  <joint name="arm_to_hand" type="fixed">
    <parent link="ee_link"/>
    <child link="H1_base_attach"/>
    <origin rpy="1.57079632679 3.14159265359 1.57079632679" xyz="0.012 0.0 0.0"/>
  </joint>

  <!-- Pilz arm -->
  <!--     <xacro:prbt parent="cabinet_link" prefix="pilz">
    <origin xyz="0 0 0." rpy="0 0 0" />
  </xacro:prbt>
 -->

</robot>

