<?xml version="1.0" ?>
<!-- =================================================================================== -->
<!-- |    This document was autogenerated by xacro from indyrp2.xacro                  | -->
<!-- |    EDITING THIS FILE BY HAND IS NOT RECOMMENDED                                 | -->
<!-- =================================================================================== -->
<robot name="indyrp2">
  <material name="black">
    <color rgba="0.0 0.0 0.0 1.0"/>
  </material>
  <material name="blue">
    <color rgba="0.0 0.0 0.8 1.0"/>
  </material>
  <material name="green">
    <color rgba="0.0 0.8 0.0 1.0"/>
  </material>
  <material name="grey_">
    <color rgba="0.2 0.2 0.2 1.0"/>
  </material>
  <material name="orange">
    <color rgba="1.0 0.4235294117647059 0.0392156862745098 1.0"/>
  </material>
  <material name="brown">
    <color rgba="0.8705882352941177 0.8117647058823529 0.7647058823529411 1.0"/>
  </material>
  <material name="red">
    <color rgba="0.8 0.0 0.0 1.0"/>
  </material>
  <material name="white">
    <color rgba="1.0 1.0 1.0 1.0"/>
  </material>
  <material name="metal">
    <color rgba="0.768627450980392 0.749019607843137 0.729411764705882 1"/>
  </material>
  <material name="metal_grey">
    <color rgba="0.501960784313725 0.501960784313725 0.501960784313725 1"/>
  </material>
  <material name="metal_white">
    <color rgba="0.866666666666667 0.866666666666667 0.890196078431373 1"/>
  </material>

  <link name="link0">
    <visual>
      <origin rpy="0 0 0" xyz="0 0 0"/>
      <geometry>
        <mesh filename="package://indyrp2_description/meshes/stl/IndyRP2_0.stl"/>
      </geometry>
      <material name="metal_grey"/>
    </visual>

    <inertial>
      <origin rpy="0 0 0" xyz="0.00131966 -0.00000218 0.03212832"/>
      <mass value="1.67030785"/>
      <inertia ixx="+0.00661309" ixy="+0.00000183" ixz="+0.00002695" iyy="+0.00644765" iyz="-0.00000027" izz="+0.00792090"/>
    </inertial>
  </link>
  <link name="link1">
    <visual>
      <origin rpy="0 0 0" xyz="0 0 0"/>
      <geometry>
        <mesh filename="package://indyrp2_description/meshes/stl/IndyRP2_1.stl"/>
      </geometry>
      <material name="metal_grey"/>
    </visual>

    <inertial>
      <origin rpy="0 0 0" xyz="-0.00023749 -0.04310313 0.13245396"/>
      <mass value="11.44444535"/>
      <inertia ixx="+0.35065005" ixy="+0.00011931" ixz="-0.00037553" iyy="+0.30479800" iyz="-0.10984447" izz="+0.06003147"/>
    </inertial>
  </link>
  <link name="link2">
    <visual>
      <origin rpy="0 0 0" xyz="0 0 0"/>
      <geometry>
        <mesh filename="package://indyrp2_description/meshes/stl/IndyRP2_2.stl"/>
      </geometry>
      <material name="metal_grey"/>
    </visual>

    <inertial>
      <origin rpy="0 0 0" xyz="-0.21209188 -0.00001715 0.07901191"/>
      <mass value="4.43308185"/>
      <inertia ixx="+0.03742681" ixy="+0.00003176" ixz="-0.07906734" iyy="+0.32119654" iyz="-0.00000808" izz="+0.29396155"/>
    </inertial>
  </link>
  <link name="link3">
    <visual>
      <origin rpy="0 0 0" xyz="0 0 0"/>
      <geometry>
        <mesh filename="package://indyrp2_description/meshes/stl/IndyRP2_3.stl"/>
      </geometry>
      <material name="metal_grey"/>
    </visual>

    <inertial>
      <origin rpy="0 0 0" xyz="0.00003637 0.07143055 0.07746050"/>
      <mass value="2.87045928"/>
      <inertia ixx="+0.04098160" ixy="+0.00000747" ixz="+0.00000916" iyy="+0.02106773" iyz="+0.01817157" izz="+0.02277477"/>
    </inertial>
  </link>
  <link name="link4">
    <visual>
      <origin rpy="0 0 0" xyz="0 0 0"/>
      <geometry>
        <mesh filename="package://indyrp2_description/meshes/stl/IndyRP2_4.stl"/>
      </geometry>
      <material name="metal_grey"/>
    </visual>

    <inertial>
      <origin rpy="0 0 0" xyz="-0.16804016 0.00021421 -0.07000383"/>
      <mass value="2.68206064"/>
      <inertia ixx="+0.01617210" ixy="-0.00011817" ixz="+0.03341882" iyy="+0.11364055" iyz="-0.00004371" izz="+0.10022522"/>
    </inertial>
  </link>
  <link name="link5">
    <visual>
      <origin rpy="0 0 0" xyz="0 0 0"/>
      <geometry>
        <mesh filename="package://indyrp2_description/meshes/stl/IndyRP2_5.stl"/>
      </geometry>
      <material name="metal_grey"/>
    </visual>

    <inertial>
      <origin rpy="0 0 0" xyz="-0.00026847 -0.07098440 0.07649128"/>
      <mass value="2.12987371"/>
      <inertia ixx="+0.02798891" ixy="+0.00003893" ixz="-0.00004768" iyy="+0.01443076" iyz="-0.01266296" izz="+0.01496211"/>
    </inertial>
  </link>
  <link name="link6">
    <visual>
      <origin rpy="0 0 0" xyz="0 0 0"/>
      <geometry>
        <mesh filename="package://indyrp2_description/meshes/stl/IndyRP2_6.stl"/>
      </geometry>
      <material name="metal_grey"/>
    </visual>

    <inertial>
      <origin rpy="0 0 0" xyz="-0.09796232 -0.00023114 0.06445892"/>
      <mass value="2.22412271"/>
      <inertia ixx="+0.01105297" ixy="+0.00005517" ixz="-0.01481977" iyy="+0.03698291" iyz="-0.00003740" izz="+0.02754795"/>
    </inertial>
  </link>
  <link name="link7">
    <visual>
      <origin rpy="0 0 0" xyz="0 0 0"/>
      <geometry>
        <mesh filename="package://indyrp2_description/meshes/stl/IndyRP2_7.stl"/>
      </geometry>
      <material name="metal_grey"/>
    </visual>

    <inertial>
      <origin rpy="0 0 0" xyz="0.00008147 -0.00046556 0.03079097"/>
      <mass value="0.38254932"/>
      <inertia ixx="+0.00078982" ixy="-0.00000034" ixz="+0.00000083" iyy="+0.00079764" iyz="-0.00000508" izz="+0.00058319"/>
    </inertial>
  </link>
  <link name="tcp">
    <inertial>
      <mass value="0.000001" />
      <origin xyz="0.0 0.0 0.0" rpy="0 0 0" />
      <inertia ixx="0.000001" ixy="0" ixz="0" iyy="0.000001" iyz="0" izz="0.000001" />
    </inertial>
  </link>

  <joint name="joint0" type="continuous">
    <parent link="link0"/>
    <child link="link1"/>
    <origin rpy="0 0 0" xyz="+0.00000000 +0.00000000 +0.07720000"/>
    <axis xyz="0 0 1"/>
  </joint>
  <joint name="joint1" type="continuous">
    <parent link="link1"/>
    <child link="link2"/>
    <origin rpy="1.5707963267948966 1.5707963267948966 0" xyz="+0.00000000 -0.10930000 +0.22280000"/>
    <axis xyz="0 0 1"/>
  </joint>
  <joint name="joint2" type="continuous">
    <parent link="link2"/>
    <child link="link3"/>
    <origin rpy="-1.5707963267948966 0 1.5707963267948966" xyz="-0.38400000 +0.00000000 +0.08470000"/>
    <axis xyz="0 0 1"/>
  </joint>
  <joint name="joint3" type="continuous">
    <parent link="link3"/>
    <child link="link4"/>
    <origin rpy="1.5707963267948966 1.5707963267948966 0" xyz="+0.00000000 +0.11530000 +0.06550000"/>
    <axis xyz="0 0 1"/>
  </joint>
  <joint name="joint4" type="continuous">
    <parent link="link4"/>
    <child link="link5"/>
    <origin rpy="-1.5707963267948966 0 1.5707963267948966" xyz="-0.26650000 +0.00000000 -0.07470000"/>
    <axis xyz="0 0 1"/>
  </joint>
  <joint name="joint5" type="continuous">
    <parent link="link5"/>
    <child link="link6"/>
    <origin rpy="1.5707963267948966 1.5707963267948966 0" xyz="+0.00000000 -0.11430000 +0.08350000"/>
    <axis xyz="0 0 1"/>
  </joint>
  <joint name="joint6" type="continuous">
    <parent link="link6"/>
    <child link="link7"/>
    <origin rpy="-1.5707963267948966 0 1.5707963267948966" xyz="-0.16800000 +0.00000000 +0.06870000"/>
    <axis xyz="0 0 1"/>
  </joint>
  <joint name="indyrp2_tcp" type="fixed">
    <parent link="link7"/>
    <child link="tcp"/>
    <origin rpy="0 0 0" xyz="0 0 0.06"/>
  </joint>
</robot>

