<?xml version="1.0" ?>
<!-- =================================================================================== -->
<!-- |    This document was autogenerated by xacro from indyrp2.xacro                  | -->
<!-- |    EDITING THIS FILE BY HAND IS NOT RECOMMENDED                                 | -->
<!-- =================================================================================== -->
<robot name="indyrp2">
  <material name="black">
    <color rgba="0.0 0.0 0.0 1.0"/>
  </material>
  <material name="blue">
    <color rgba="0.0 0.0 0.8 1.0"/>
  </material>
  <material name="green">
    <color rgba="0.0 0.8 0.0 1.0"/>
  </material>
  <material name="grey_">
    <color rgba="0.2 0.2 0.2 1.0"/>
  </material>
  <material name="orange">
    <color rgba="1.0 0.4235294117647059 0.0392156862745098 1.0"/>
  </material>
  <material name="brown">
    <color rgba="0.8705882352941177 0.8117647058823529 0.7647058823529411 1.0"/>
  </material>
  <material name="red">
    <color rgba="0.8 0.0 0.0 1.0"/>
  </material>
  <material name="white">
    <color rgba="1.0 1.0 1.0 1.0"/>
  </material>
  <material name="metal">
    <color rgba="0.768627450980392 0.749019607843137 0.729411764705882 1"/>
  </material>
  <material name="metal_grey">
    <color rgba="0.501960784313725 0.501960784313725 0.501960784313725 1"/>
  </material>
  <material name="metal_white">
    <color rgba="0.866666666666667 0.866666666666667 0.890196078431373 1"/>
  </material>
  <link name="world"/>
  <link name="link0">
    <visual>
      <origin rpy="0 0 0" xyz="0 0 0"/>
      <geometry>
        <mesh filename="package://indyrp2_description/meshes/stl/IndyRP2_0.stl"/>
      </geometry>
      <material name="metal_grey"/>
    </visual>
    <collision>
      <origin rpy="0 0 0" xyz="0 0 0"/>
      <geometry>
        <mesh filename="package://indyrp2_description/meshes/stl/IndyRP2_0.stl"/>
      </geometry>
    </collision>
    <inertial>
      <origin rpy="0 0 0" xyz="0 0 0"/>
      <mass value="5.44309"/>
      <inertia ixx="0.0236" ixy="0" ixz="0" iyy="0.0234" iyz="0.0001" izz="0.0137"/>
    </inertial>
  </link>
  <link name="link1">
    <visual>
      <origin rpy="0 0 0" xyz="0 0 0"/>
      <geometry>
        <mesh filename="package://indyrp2_description/meshes/stl/IndyRP2_1.stl"/>
      </geometry>
      <material name="metal_grey"/>
    </visual>
    <collision>
      <origin rpy="0 0 0" xyz="0 0 0"/>
      <geometry>
        <mesh filename="package://indyrp2_description/meshes/stl/IndyRP2_1.stl"/>
      </geometry>
    </collision>
    <inertial>
      <origin rpy="0 0 0" xyz="0 0 0"/>
      <mass value="5.50328"/>
      <inertia ixx="0.0227" ixy="0" ixz="0" iyy="0.0121" iyz="0.0013" izz="0.0212"/>
    </inertial>
  </link>
  <link name="link2">
    <visual>
      <origin rpy="0 0 0" xyz="0 0 0"/>
      <geometry>
        <mesh filename="package://indyrp2_description/meshes/stl/IndyRP2_2.stl"/>
      </geometry>
      <material name="metal_grey"/>
    </visual>
    <collision>
      <origin rpy="0 0 0" xyz="0 0 0"/>
      <geometry>
        <mesh filename="package://indyrp2_description/meshes/stl/IndyRP2_2.stl"/>
      </geometry>
    </collision>
    <inertial>
      <origin rpy="0 0 0" xyz="0 0 0"/>
      <mass value="5.95397"/>
      <inertia ixx="0.1175" ixy="00" ixz="0" iyy="0.1172" iyz="0.0037" izz="0.0131"/>
    </inertial>
  </link>
  <link name="link3">
    <visual>
      <origin rpy="0 0 0" xyz="0 0 0"/>
      <geometry>
        <mesh filename="package://indyrp2_description/meshes/stl/IndyRP2_3.stl"/>
      </geometry>
      <material name="metal_grey"/>
    </visual>
    <collision>
      <origin rpy="0 0 0" xyz="0 0 0"/>
      <geometry>
        <mesh filename="package://indyrp2_description/meshes/stl/IndyRP2_3.stl"/>
      </geometry>
    </collision>
    <inertial>
      <origin rpy="0 0 0" xyz="0 0 0"/>
      <mass value="4.08259"/>
      <inertia ixx="0.0132" ixy="0" ixz="0" iyy="0.0068" iyz="-0.0008" izz="0.0125"/>
    </inertial>
  </link>
  <link name="link4">
    <visual>
      <origin rpy="0 0 0" xyz="0 0 0"/>
      <geometry>
        <mesh filename="package://indyrp2_description/meshes/stl/IndyRP2_4.stl"/>
      </geometry>
      <material name="metal_grey"/>
    </visual>
    <collision>
      <origin rpy="0 0 0" xyz="0 0 0"/>
      <geometry>
        <mesh filename="package://indyrp2_description/meshes/stl/IndyRP2_4.stl"/>
      </geometry>
    </collision>
    <inertial>
      <origin rpy="0 0 0" xyz="0 0 0"/>
      <mass value="4.02733"/>
      <inertia ixx="0.0674" ixy="0" ixz="0" iyy="0.067" iyz="-0.0027" izz="0.0071"/>
    </inertial>
  </link>
  <link name="link5">
    <visual>
      <origin rpy="0 0 0" xyz="0 0 0"/>
      <geometry>
        <mesh filename="package://indyrp2_description/meshes/stl/IndyRP2_5.stl"/>
      </geometry>
      <material name="metal_grey"/>
    </visual>
    <collision>
      <origin rpy="0 0 0" xyz="0 0 0"/>
      <geometry>
        <mesh filename="package://indyrp2_description/meshes/stl/IndyRP2_5.stl"/>
      </geometry>
    </collision>
    <inertial>
      <origin rpy="0 0 0" xyz="0 0 0"/>
      <mass value="2.52863"/>
      <inertia ixx="0.0066" ixy="0" ixz="0" iyy="0.0033" iyz="0.0003" izz="0.0062"/>
    </inertial>
  </link>
  <link name="link6">
    <visual>
      <origin rpy="0 0 0" xyz="0 0 0"/>
      <geometry>
        <mesh filename="package://indyrp2_description/meshes/stl/IndyRP2_6.stl"/>
      </geometry>
      <material name="metal_grey"/>
    </visual>
    <collision>
      <origin rpy="0 0 0" xyz="0 0 0"/>
      <geometry>
        <mesh filename="package://indyrp2_description/meshes/stl/IndyRP2_6.stl"/>
      </geometry>
    </collision>
    <inertial>
      <origin rpy="0 0 0" xyz="0 0 0"/>
      <mass value="2.03152"/>
      <inertia ixx="0.0042" ixy="0" ixz="0" iyy="0.0041" iyz="0.0003" izz="0.0018"/>
    </inertial>
  </link>
  <link name="link7">
    <visual>
      <origin rpy="0 0 0" xyz="0 0 0"/>
      <geometry>
        <mesh filename="package://indyrp2_description/meshes/stl/IndyRP2_7.stl"/>
      </geometry>
      <material name="metal_grey"/>
    </visual>
    <collision>
      <origin rpy="0 0 0" xyz="0 0 0"/>
      <geometry>
        <mesh filename="package://indyrp2_description/meshes/stl/IndyRP2_7.stl"/>
      </geometry>
    </collision>
    <inertial>
      <origin rpy="0 0 0" xyz="0 0 0"/>
      <mass value="0.17194"/>
      <inertia ixx="0.0001" ixy="0" ixz="0" iyy="0.0001" iyz="0" izz="0.0001"/>
    </inertial>
  </link>
  <link name="tcp"/>
  <joint name="global" type="fixed">
    <parent link="world"/>
    <child link="link0"/>
    <origin rpy="0 0 0" xyz="0 0 0"/>
  </joint>
  <joint name="joint0" type="continuous">
    <parent link="link0"/>
    <child link="link1"/>
    <origin rpy="0 0 0" xyz="+0.00000000 +0.00000000 +0.07720000"/>
    <axis xyz="0 0 1"/>
  </joint>
  <joint name="joint1" type="continuous">
    <parent link="link1"/>
    <child link="link2"/>
    <origin rpy="1.5707963267948966 1.5707963267948966 0" xyz="+0.00000000 -0.10930000 +0.22280000"/>
    <axis xyz="0 0 1"/>
  </joint>
  <joint name="joint2" type="continuous">
    <parent link="link2"/>
    <child link="link3"/>
    <origin rpy="-1.5707963267948966 0 1.5707963267948966" xyz="-0.38400000 +0.00000000 +0.08470000"/>
    <axis xyz="0 0 1"/>
  </joint>
  <joint name="joint3" type="continuous">
    <parent link="link3"/>
    <child link="link4"/>
    <origin rpy="1.5707963267948966 1.5707963267948966 0" xyz="+0.00000000 +0.11530000 +0.06550000"/>
    <axis xyz="0 0 1"/>
  </joint>
  <joint name="joint4" type="continuous">
    <parent link="link4"/>
    <child link="link5"/>
    <origin rpy="-1.5707963267948966 0 1.5707963267948966" xyz="-0.26650000 +0.00000000 -0.07470000"/>
    <axis xyz="0 0 1"/>
  </joint>
  <joint name="joint5" type="continuous">
    <parent link="link5"/>
    <child link="link6"/>
    <origin rpy="1.5707963267948966 1.5707963267948966 0" xyz="+0.00000000 -0.11430000 +0.08350000"/>
    <axis xyz="0 0 1"/>
  </joint>
  <joint name="joint6" type="continuous">
    <parent link="link6"/>
    <child link="link7"/>
    <origin rpy="-1.5707963267948966 0 1.5707963267948966" xyz="-0.16800000 +0.00000000 +0.06870000"/>
    <axis xyz="0 0 1"/>
  </joint>
  <joint name="indyrp2_tcp" type="fixed">
    <parent link="link7"/>
    <child link="tcp"/>
    <origin rpy="0 0 0" xyz="0 0 0.06"/>
  </joint>
</robot>

