<?xml version="1.0" encoding="utf-8"?>
<!-- This URDF was automatically created by SolidWorks to URDF Exporter! Originally created by Stephen Brawner (brawner@gmail.com) 
     Commit Version: 1.6.0-4-g7f85cfe  Build Version: 1.6.7995.38578
     For more information, please see http://wiki.ros.org/sw_urdf_exporter -->
<robot
  name="sftlink">
  <link name="link1">
    <inertial>
      <origin
        xyz="0 0 0"
        rpy="0 0 0" />
      <mass
        value="0.00000001" />
      <inertia
        ixx="0.00000001"
        ixy="0.00000001"
        ixz="0.00000001"
        iyy="0.00000001"
        iyz="0.00000001"
        izz="0.00000001" />
    </inertial>
    <visual>
      <origin

        xyz="0 0 0"
        rpy="0 0 0" />
      <geometry>
        <mesh
          filename="meshes/lower_plate.STL" />
      </geometry>
    </visual>

  </link>
 
  <joint
    name="joint1"
    type="revolute">
    <origin
      xyz="0 0 0.01"
      rpy="0 0 0" />
    <parent
      link="link1" />
    <child
      link="link2" />
    <axis
      xyz="1 0 0" />
    <limit effort="50.0" lower="-1.5709" upper="1.5709" velocity="2.4"/>
    <joint_properties damping="0" friction="0"/>
  </joint> 
 
  <link name="link2">
    <inertial>
      <origin
        xyz="0 0 0"
        rpy="0 0 0" />
      <mass
        value="0.00000001" />
      <inertia
        ixx="0.00000001"
        ixy="0.00000001"
        ixz="0.00000001"
        iyy="0.00000001"
        iyz="0.00000001"
        izz="0.00000001" />
    </inertial>
  </link>

  <joint
    name="joint2"
    type="revolute">
    <origin
      xyz="0 0 0"
      rpy="0 0 0" />
    <parent
      link="link2" />
    <child
      link="link3" />
    <axis
      xyz="0 1 0" />
    <limit effort="50.0" lower="-1.5709" upper="1.5709" velocity="2.4"/>
    <joint_properties damping="0" friction="0"/>
  </joint> 
  
  <link
    name="link3">
    <inertial>
      <origin
        xyz="-0.00225446189173149 0.000841952098791728 0.0807644877991043"
        rpy="0 0 0" />
      <mass
        value="0.24346419802046" />
      <inertia
        ixx="0.0001745781286827"
        ixy="-1.04687949786574E-06"
        ixz="1.1254808322926E-05"
        iyy="0.000223328225220146"
        iyz="1.68180762188499E-07"
        izz="0.000150182028600422" />
    </inertial>
    <visual>
      <origin
        xyz="0 0 0"
        rpy="0 0 0" />
      <geometry>
        <mesh
          filename="meshes/lower_pillar.STL" />
      </geometry>
      <material
        name="">
        <color
          rgba="0.792156862745098 0.819607843137255 0.933333333333333 1" />
      </material>
    </visual>
  </link>

  <joint
    name="joint3"
    type="prismatic">
    <origin
      xyz="0 0 0.2"
      rpy="0 0 0" />
    <parent
      link="link3" />
    <child
      link="link4" />
    <axis
      xyz="0 0 1" />
    <limit effort="50.0" lower="-0.2" upper="0.0" velocity="3.5"/>
    <joint_properties damping="0" friction="0.7"/>
  </joint>

  <link
    name="link4">
    <inertial>
      <origin
        xyz="4.84561414114279E-06 -1.26976012193017E-05 0.0625625835372048"
        rpy="0 0 0" />
      <mass
        value="0.414448305573101" />
      <inertia
        ixx="0.000585953873385061"
        ixy="-1.1243847757635E-08"
        ixz="-4.31440123925373E-09"
        iyy="0.000581924454364926"
        iyz="-1.09417379936541E-08"
        izz="0.000859317069814105" />
    </inertial>
    <visual>
      <origin
        xyz="0 0 0"
        rpy="0 0 0" />
      <geometry>
        <mesh
          filename="meshes/upper_pillar.STL" />
      </geometry>
      <material
        name="">
        <color
          rgba="0.792156862745098 0.819607843137255 0.933333333333333 1" />
      </material>
    </visual>
  </link>
  
  <joint
    name="joint4"
    type="revolute">
    <origin
      xyz="0 0 0.2"
      rpy="0 0 0" />
    <parent
      link="link4" />
    <child
      link="link5" />
    <axis
      xyz="1 0 0" />
    <limit effort="50.0" lower="-2.7925" upper="2.7925" velocity="2.4"/>
    <joint_properties damping="0.0" friction="0.7"/>
  </joint>

  <link name="link5">
    <inertial>
      <origin
        xyz="0 0 0"
        rpy="0 0 0" />
      <mass
        value="0.00000001" />
      <inertia
        ixx="0.00000001"
        ixy="0.00000001"
        ixz="0.00000001"
        iyy="0.00000001"
        iyz="0.00000001"
        izz="0.00000001" />
    </inertial>
  </link>

  <joint
    name="joint5"
    type="revolute">
    <origin
      xyz="0.0 0 0.0"
      rpy="0 0 0" />
    <parent
      link="link5" />
    <child
      link="link6" />
    <axis
      xyz="0 1 0" />
    <limit effort="50.0" lower="-0.349" upper="1.745" velocity="2.4"/>
    <joint_properties damping="0.0" friction="0.7"/>
  </joint>

  <link
    name="link6">
    <inertial>
      <origin
        xyz="0.0 0.0 0.005"
        rpy="0 0 0" />
      <mass
        value="0.18283" />
      <inertia
        ixx="0.0002941"
        ixy="1.0245E-06"
        ixz="2.6436E-06"
        iyy="0.00031881"
        iyz="-1.4053E-07"
        izz="0.00047776" />
    </inertial>
    <visual>
      <origin
        xyz="0 0 0"
        rpy="0 0 0" />
      <geometry>
        <mesh
          filename="meshes/upper_plate.STL" />
      </geometry>
      <material
        name="">
        <color
          rgba="0.79216 0.81961 0.93333 1" />
      </material>
    </visual>
  </link>

  <joint name="endeffector" type="fixed">
    <origin rpy="0.0 -1.57079632679 0.0 " xyz="0.0 0.0 0.01"/>
    <parent link="link6"/>
    <child link="tool0"/>
  </joint>

  <link name="tool0">
      <inertial>
          <mass value="0.000001" />
          <origin xyz="0.0 0.0 0.0" rpy="0 0 0" />
          <inertia ixx="0.000001" ixy="0" ixz="0" iyy="0.000001" iyz="0" izz="0.000001" />
      </inertial>
  </link>

</robot>
